<mujoco model="ngr_simple">
  <default>
    <default class="robot">
      <default class="motor">
        <joint />
        <motor />
      </default>
      <default class="visual">
        <geom material="visualgeom" contype="0" conaffinity="0" group="2" />
      </default>
      <default class="collision">
        <geom material="collision_material" condim="3" contype="0" conaffinity="1" priority="1" group="1" solref="0.005 1" solimp="0.99 0.999 1e-05" friction="1 0.01 0.01" />
      </default>
    </default>
  </default>

  <compiler angle="radian" />

  <asset>
    <material name="gray" rgba="0.5 0.5 0.5 0.7" />
    <material name="black" rgba="0.0 0.0 0.0 0.7" />
    <material name="blue" rgba="0 0 0.8 0.8" />
    <material name="red" rgba="0.8 0.0 0.2 0.8" />
    <material name="purple" rgba="0.5 0.0 0.5 0.8" />
    <material name="green" rgba="0.0 1.0 0.0 0.8" />
    <material name="default_material" rgba="0.7 0.7 0.7 1" />
    <material name="collision_material" rgba="1.0 0.28 0.1 0.9" />
  </asset>

  <worldbody>
    <body name="body" pos="0.00000000 0.00000000 0.29584766" quat="1 0 0 0" childclass="robot">
      <freejoint name="floating_base" />
      <geom name="body_collision" pos="0 0 0" quat="1 0 0 0" type="box" size="0.025 0.125 0.095" class="collision" />
      <geom name="body_visual" pos="0 0 0" quat="1.0 0.0 0.0 0.0" material="gray" type="box" size="0.44 0.125 0.095" class="visual" />
      <body name="hip0" pos="0.325 0.1575 0" quat="1.0 0.0 0.0 0.0">
        <joint name="8" type="hinge" ref="0.0" class="motor" axis="1 0 0" />
        <inertial mass="2.75" diaginertia="0.00891458 0.0100573 0.01533698" />
        <geom name="hip0_collision" pos="0.0 0 0" quat="1.0 0.0 0.0 0.0" type="box" size="0.0975 0.085 0.05" class="collision" />
        <geom name="hip0_visual" pos="0.0 0 0" quat="1.0 0.0 0.0 0.0" material="red" type="box" size="0.0975 0.085 0.05" class="visual" />
        <body name="upper0" pos="-.0975 0 0" quat="0.9689124217106447 0.0 -0.24740395925452294 0.0">
          <joint name="0" type="hinge" ref="0.0" class="motor" axis="0 -1 0" />
          <inertial pos="-0.125 0 0" quat="1.0 0.0 0.0 0.0" mass="0.625" diaginertia="0.0003125 0.0040625 0.0040625" />
          <geom name="upper0_collision" pos="-0.125 0 0" quat="1.0 0.0 0.0 0.0" type="box" size="0.125 0.022 0.03" class="collision" />
          <geom name="upper0_visual" pos="-0.125 0.0 0" quat="1.0 0.0 0.0 0.0" material="blue" type="box" size="0.125 0.022 0.03" class="visual" />
          <body name="lower0" pos="-0.25 0 0" quat="0.9286646355765102 0.0 0.3709204694129827 0.0">
            <joint name="1" type="hinge" ref="0.0" class="motor" axis="0 1 0" />
            <inertial pos="0.14 0 0" quat="1.0 0.0 0.0 0.0" mass="0.2" diaginertia="1.21e-05 0.0013127167 0.0013127167" />
            <geom name="lower0_collision_0" pos="0.14 0 0" quat="0.7071067811847432 0.0 0.7071067811883519 0.0" type="cylinder" size="0.011 0.14" class="collision" />
            <geom name="lower0_collision_1" pos="0.28 0 0" quat="0.7071067811847432 0.0 0.7071067811883519 0.0" type="sphere" size="0.011" class="collision" />
            <geom name="lower0_visual_0" pos="0.14 0 0" quat="0.7071067811847432 0.0 0.7071067811883519 0.0" material="black" type="cylinder" size="0.011 0.14" class="visual" />
            <geom name="lower0_visual_1" pos="0.28 0 0" quat="0.7071067811847432 0.0 0.7071067811883519 0.0" material="green" type="sphere" size="0.011" class="visual" />
          </body>
        </body>
      </body>
      <body name="hip1" pos="-0.325 0.1575 0" quat="1.0 0.0 0.0 0.0">
        <joint name="9" type="hinge" ref="0.0" class="motor" axis="1 0 0" />
        <inertial mass="2.75" diaginertia="0.00891458 0.0100573 0.01533698" />
        <geom name="hip1_collision" pos="0.0 0 0" quat="1.0 0.0 0.0 0.0" type="box" size="0.0975 0.085 0.05" class="collision" />
        <geom name="hip1_visual" pos="0.0 0 0" quat="1.0 0.0 0.0 0.0" material="purple" type="box" size="0.0975 0.085 0.05" class="visual" />
        <body name="upper1" pos="-.0975 0 0" quat="0.9689124217106447 0.0 -0.24740395925452294 0.0">
          <joint name="2" type="hinge" ref="0.0" class="motor" axis="0 -1 0" />
          <inertial pos="-0.125 0 0" quat="1.0 0.0 0.0 0.0" mass="0.625" diaginertia="0.0003125 0.0040625 0.0040625" />
          <geom name="upper1_collision" pos="-0.125 0 0" quat="1.0 0.0 0.0 0.0" type="box" size="0.125 0.022 0.03" class="collision" />
          <geom name="upper1_visual" pos="-0.125 0.0 0" quat="1.0 0.0 0.0 0.0" material="blue" type="box" size="0.125 0.022 0.03" class="visual" />
          <body name="lower1" pos="-0.25 0 0" quat="0.9286646355765102 0.0 0.3709204694129827 0.0">
            <joint name="3" type="hinge" ref="0.0" class="motor" axis="0 1 0" />
            <inertial pos="0.14 0 0" quat="1.0 0.0 0.0 0.0" mass="0.2" diaginertia="1.21e-05 0.0013127167 0.0013127167" />
            <geom name="lower1_collision_0" pos="0.14 0 0" quat="0.7071067811847432 0.0 0.7071067811883519 0.0" type="cylinder" size="0.011 0.14" class="collision" />
            <geom name="lower1_collision_1" pos="0.28 0 0" quat="0.7071067811847432 0.0 0.7071067811883519 0.0" type="sphere" size="0.011" class="collision" />
            <geom name="lower1_visual_0" pos="0.14 0 0" quat="0.7071067811847432 0.0 0.7071067811883519 0.0" material="black" type="cylinder" size="0.011 0.14" class="visual" />
            <geom name="lower1_visual_1" pos="0.28 0 0" quat="0.7071067811847432 0.0 0.7071067811883519 0.0" material="green" type="sphere" size="0.011" class="visual" />
          </body>
        </body>
      </body>
      <body name="hip2" pos="0.325 -0.1575 0" quat="1.0 0.0 0.0 0.0">
        <joint name="10" type="hinge" ref="0.0" class="motor" axis="1 0 0" />
        <inertial mass="2.75" diaginertia="0.00891458 0.0100573 0.01533698" />
        <geom name="hip2_collision" pos="0.0 0 0" quat="1.0 0.0 0.0 0.0" type="box" size="0.0975 0.085 0.05" class="collision" />
        <geom name="hip2_visual" pos="0.0 0 0" quat="1.0 0.0 0.0 0.0" material="red" type="box" size="0.0975 0.085 0.05" class="visual" />
        <body name="upper2" pos="-.0975 0 0" quat="0.9689124217106447 0.0 -0.24740395925452294 0.0">
          <joint name="4" type="hinge" ref="0.0" class="motor" axis="0 -1 0" />
          <inertial pos="-0.125 0 0" quat="1.0 0.0 0.0 0.0" mass="0.625" diaginertia="0.0003125 0.0040625 0.0040625" />
          <geom name="upper2_collision" pos="-0.125 0 0" quat="1.0 0.0 0.0 0.0" type="box" size="0.125 0.022 0.03" class="collision" />
          <geom name="upper2_visual" pos="-0.125 0.0 0" quat="1.0 0.0 0.0 0.0" material="blue" type="box" size="0.125 0.022 0.03" class="visual" />
          <body name="lower2" pos="-0.25 0 0" quat="0.9286646355765102 0.0 0.3709204694129827 0.0">
            <joint name="5" type="hinge" ref="0.0" class="motor" axis="0 1 0" />
            <inertial pos="0.14 0 0" quat="1.0 0.0 0.0 0.0" mass="0.2" diaginertia="1.21e-05 0.0013127167 0.0013127167" />
            <geom name="lower2_collision_0" pos="0.14 0 0" quat="0.7071067811847432 0.0 0.7071067811883519 0.0" type="cylinder" size="0.011 0.14" class="collision" />
            <geom name="lower2_collision_1" pos="0.28 0 0" quat="0.7071067811847432 0.0 0.7071067811883519 0.0" type="sphere" size="0.011" class="collision" />
            <geom name="lower2_visual_0" pos="0.14 0 0" quat="0.7071067811847432 0.0 0.7071067811883519 0.0" material="black" type="cylinder" size="0.011 0.14" class="visual" />
            <geom name="lower2_visual_1" pos="0.28 0 0" quat="0.7071067811847432 0.0 0.7071067811883519 0.0" material="green" type="sphere" size="0.011" class="visual" />
          </body>
        </body>
      </body>
      <body name="hip3" pos="-0.325 -0.1575 0" quat="1.0 0.0 0.0 0.0">
        <joint name="11" type="hinge" ref="0.0" class="motor" axis="1 0 0" />
        <inertial mass="2.75" diaginertia="0.00891458 0.0100573 0.01533698" />
        <geom name="hip3_collision" pos="0.0 0 0" quat="1.0 0.0 0.0 0.0" type="box" size="0.0975 0.085 0.05" class="collision" />
        <geom name="hip3_visual" pos="0.0 0 0" quat="1.0 0.0 0.0 0.0" material="purple" type="box" size="0.0975 0.085 0.05" class="visual" />
        <body name="upper3" pos="-.0975 0 0" quat="0.9689124217106447 0.0 -0.24740395925452294 0.0">
          <joint name="6" type="hinge" ref="0.0" class="motor" axis="0 -1 0" />
          <inertial pos="-0.125 0 0" quat="1.0 0.0 0.0 0.0" mass="0.625" diaginertia="0.0003125 0.0040625 0.0040625" />
          <geom name="upper3_collision" pos="-0.125 0 0" quat="1.0 0.0 0.0 0.0" type="box" size="0.125 0.022 0.03" class="collision" />
          <geom name="upper3_visual" pos="-0.125 0.0 0" quat="1.0 0.0 0.0 0.0" material="blue" type="box" size="0.125 0.022 0.03" class="visual" />
          <body name="lower3" pos="-0.25 0 0" quat="0.9286646355765102 0.0 0.3709204694129827 0.0">
            <joint name="7" type="hinge" ref="0.0" class="motor" axis="0 1 0" />
            <inertial pos="0.14 0 0" quat="1.0 0.0 0.0 0.0" mass="0.2" diaginertia="1.21e-05 0.0013127167 0.0013127167" />
            <geom name="lower3_collision_0" pos="0.14 0 0" quat="0.7071067811847432 0.0 0.7071067811883519 0.0" type="cylinder" size="0.011 0.14" class="collision" />
            <geom name="lower3_collision_1" pos="0.28 0 0" quat="0.7071067811847432 0.0 0.7071067811883519 0.0" type="sphere" size="0.011" class="collision" />
            <geom name="lower3_visual_0" pos="0.14 0 0" quat="0.7071067811847432 0.0 0.7071067811883519 0.0" material="black" type="cylinder" size="0.011 0.14" class="visual" />
            <geom name="lower3_visual_1" pos="0.28 0 0" quat="0.7071067811847432 0.0 0.7071067811883519 0.0" material="green" type="sphere" size="0.011" class="visual" />
          </body>
        </body>
      </body>
      <site name="body_site" pos="0 0 0" quat="1 0 0 0" />
      <camera name="front_camera" mode="track" fovy="90.0" quat="4.329780281177467e-17 4.329780281177466e-17 0.7071067811865475 0.7071067811865476" pos="0.0 2.0 0.5" />
      <camera name="side_camera" mode="track" fovy="90.0" quat="-0.5 -0.4999999999999999 0.5 0.5000000000000001" pos="-2.0 0.0 0.5" />
    </body>
  </worldbody>

  <actuator>
    <motor name="8_ctrl" joint="8" class="motor" />
    <motor name="0_ctrl" joint="0" class="motor" />
    <motor name="1_ctrl" joint="1" class="motor" />
    <motor name="9_ctrl" joint="9" class="motor" />
    <motor name="2_ctrl" joint="2" class="motor" />
    <motor name="3_ctrl" joint="3" class="motor" />
    <motor name="10_ctrl" joint="10" class="motor" />
    <motor name="4_ctrl" joint="4" class="motor" />
    <motor name="5_ctrl" joint="5" class="motor" />
    <motor name="11_ctrl" joint="11" class="motor" />
    <motor name="6_ctrl" joint="6" class="motor" />
    <motor name="7_ctrl" joint="7" class="motor" />
  </actuator>

  <contact>
    <exclude body1="body" body2="hip0" />
    <exclude body1="hip0" body2="upper0" />
    <exclude body1="upper0" body2="lower0" />
    <exclude body1="body" body2="hip1" />
    <exclude body1="hip1" body2="upper1" />
    <exclude body1="upper1" body2="lower1" />
    <exclude body1="body" body2="hip2" />
    <exclude body1="hip2" body2="upper2" />
    <exclude body1="upper2" body2="lower2" />
    <exclude body1="body" body2="hip3" />
    <exclude body1="hip3" body2="upper3" />
    <exclude body1="upper3" body2="lower3" />
  </contact>

  <sensor>
    <framepos name="body_site_pos" objtype="site" objname="body_site" />
    <framequat name="body_site_quat" objtype="site" objname="body_site" />
    <framelinvel name="body_site_linvel" objtype="site" objname="body_site" />
    <frameangvel name="body_site_angvel" objtype="site" objname="body_site" />
    <velocimeter name="body_site_vel" site="body_site" />
  </sensor>
</mujoco>