<?xml version='1.0'?>
<sdf version='1.6'>
<world name='default'>
	<model name="spider">
	
		<!-- Prevents the robot from falling through the world when visualized in Gazebo. -->
		<joint name="body2world" type="fixed">
			<parent>world</parent>
			<child>body</child>
		</joint>
		
		<!--TODO: Fix all inertia/mass values!-->

		<!-- Floating base link -->
		
		<link name="body">
			<pose frame=''>0 0 0 0 0 0</pose>
			<inertial>
				<mass>5</mass>
				<inertia>
					<ixx>5</ixx>
					<ixy>0</ixy>
					<ixz>0</ixz>
					<iyy>5</iyy>
					<iyz>0</iyz>
					<izz>5</izz>
				</inertia>
			</inertial>
			<collision name="body_collision">
				<geometry>
					<cylinder>
						<length>0.1</length>
						<radius>0.3</radius>
					</cylinder>
				</geometry>
			</collision>
			<visual name="body_visual">
				<geometry>
					<cylinder>
						<length>0.1</length>
						<radius>0.3</radius>
					</cylinder>
				</geometry>
			</visual>
		</link>
		
		<!-- Leg 1 links -->
		
		<!-- A temporary link, for the temporary solution of testing
		this file using revolute instead of universal joints -->
		<link name="trochanter_1">
			<pose frame=''>0 0 0 0 0 0</pose>
			<inertial>
				<pose frame=''>0 0.54 0 1.57 1.57 0</pose>
				<mass>5</mass>
				<inertia>
					<ixx>5</ixx>
					<ixy>0</ixy>
					<ixz>0</ixz>
					<iyy>5</iyy>
					<iyz>0</iyz>
					<izz>5</izz>
				</inertia>
			</inertial>
			<collision name="trochanter_1_collision">
				<pose frame=''>0 0.54 0 1.57 1.57 0</pose>
				<geometry>
					<cylinder>
						<length>0.001</length>
						<radius>0.04</radius>
					</cylinder>
				</geometry>
			</collision>
			<visual name="trochanter_1_visual">
				<pose frame=''>0 0.54 0 1.57 1.57 0</pose>
				<geometry>
					<cylinder>
						<length>0.001</length>
						<radius>0.04</radius>
					</cylinder>
				</geometry>
				<material>
					<ambient>0 1 0 0.6</ambient>
					<diffuse>0 1 0 0.6</diffuse>
				</material>
			</visual>
		</link>

		<link name="femur_1">
			<pose frame=''>0 0 0 0 0 0</pose>
			<inertial>
				<pose frame=''>0 0.54 0 1.57 1.57 0</pose>
				<mass>5</mass>
				<inertia>
					<ixx>5</ixx>
					<ixy>0</ixy>
					<ixz>0</ixz>
					<iyy>5</iyy>
					<iyz>0</iyz>
					<izz>5</izz>
				</inertia>
			</inertial>
			<collision name="femur_1_collision">
				<pose frame=''>0 0.54 0 1.57 1.57 0</pose>
				<geometry>
					<cylinder>
						<length>0.48</length>
						<radius>0.04</radius>
					</cylinder>
				</geometry>
			</collision>
			<visual name="femur_1_visual">
				<pose frame=''>0 0.54 0 1.57 1.57 0</pose>
				<geometry>
					<cylinder>
						<length>0.48</length>
						<radius>0.04</radius>
					</cylinder>
				</geometry>
				<material>
					<ambient>0 1 0 0.6</ambient>
					<diffuse>0 1 0 0.6</diffuse>
				</material>
			</visual>
		</link>
		
		<link name="tibia_1">
			<pose frame=''>0 0 0 0 0 0</pose>
			<inertial>
				<pose frame=''>0 1.02 0 1.57 1.57 0</pose>
				<mass>5</mass>
				<inertia>
					<ixx>5</ixx>
					<ixy>0</ixy>
					<ixz>0</ixz>
					<iyy>5</iyy>
					<iyz>0</iyz>
					<izz>5</izz>
				</inertia>
			</inertial>
			<collision name="tibia_1_collision">
				<pose frame=''>0 1.02 0 1.57 1.57 0</pose>
				<geometry>
					<cylinder>
						<length>0.48</length>
						<radius>0.04</radius>
					</cylinder>
				</geometry>
			</collision>
			<visual name="tibia_1_visual">
				<pose frame=''>0 1.02 0 1.57 1.57 0</pose>
				<geometry>
					<cylinder>
						<length>0.48</length>
						<radius>0.04</radius>
					</cylinder>
				</geometry>
				<material>
					<ambient>0 1 0 0.6</ambient>
					<diffuse>0 1 0 0.6</diffuse>
				</material>
			</visual>
		</link>
		
		<link name="tarsus_1">
			<pose frame=''>0 0 0 0 0 0</pose>
			<inertial>
				<pose frame=''>0 1.5 0 1.57 1.57 0</pose>
				<mass>5</mass>
				<inertia>
					<ixx>5</ixx>
					<ixy>0</ixy>
					<ixz>0</ixz>
					<iyy>5</iyy>
					<iyz>0</iyz>
					<izz>5</izz>
				</inertia>
			</inertial>
			<collision name="tarsus_1_collision">
				<pose frame=''>0 1.5 0 1.57 1.57 0</pose>
				<geometry>
					<cylinder>
						<length>0.48</length>
						<radius>0.04</radius>
					</cylinder>
				</geometry>
			</collision>
			<visual name="tarsus_1_visual">
				<pose frame=''>0 1.5 0 1.57 1.57 0</pose>
				<geometry>
					<cylinder>
						<length>0.48</length>
						<radius>0.04</radius>
					</cylinder>
				</geometry>
				<material>
					<ambient>0 1 0 0.6</ambient>
					<diffuse>0 1 0 0.6</diffuse>
				</material>
			</visual>
		</link>
		
		<!-- Leg 1 joints -->
		
		<joint name="hip_1" type="revolute">
			<parent>body</parent>
			<child>trochanter_1</child>
			<pose frame=''>0 0.3 0 0 0 0</pose>
			<axis>
				<xyz>1 0 0</xyz>
				<limit>
					<lower>-0.9162979</lower>
					<upper>0.9162979</upper>
				</limit>
				<use_parent_model_frame>0</use_parent_model_frame>
			</axis>
		</joint>
		<joint name="hip2_1" type="revolute">
			<parent>trochanter_1</parent>
			<child>femur_1</child>
			<pose frame=''>0 0.3001 0 0 0 0</pose>
			<axis>
				<xyz>0 0 1</xyz>
				<limit>
					<lower>-0.610865</lower>
					<upper>0.610865</upper>
				</limit>
				<use_parent_model_frame>0</use_parent_model_frame>
			</axis>
		</joint>
		
		<joint name="knee_1" type="revolute">
			<parent>femur_1</parent>
			<child>tibia_1</child>
			<pose frame=''>0 0.78001 0 0 0 0</pose>
			<axis>
				<xyz>1 0 0</xyz>
				<limit>
					<lower>-0.349066</lower>
					<upper>2.44346</upper>
				</limit>
			</axis>
		</joint>
		
		<joint name="ankle_1" type="revolute">
			<parent>tibia_1</parent>
			<child>tarsus_1</child>
			<pose frame=''>0 1.26001 0 0 0 0</pose>
			<axis>
				<xyz>1 0 0</xyz>
				<limit>
					<lower>-1.090831</lower>
					<upper>1.090831</upper>
				</limit>
			</axis>
		</joint>
		
		<!-- Leg 2 links -->
		
		<!-- A temporary link, for the temporary solution of testing
		this file using revolute instead of universal joints -->
		<link name="trochanter_2">
			<pose frame=''>0 0 0 0 0 0.785398</pose>
			<inertial>
				<pose frame=''>0 0.54 0 1.57 1.57 0</pose>
				<mass>5</mass>
				<inertia>
					<ixx>5</ixx>
					<ixy>0</ixy>
					<ixz>0</ixz>
					<iyy>5</iyy>
					<iyz>0</iyz>
					<izz>5</izz>
				</inertia>
			</inertial>
			<collision name="trochanter_2_collision">
				<pose frame=''>0 0.54 0 1.57 1.57 0</pose>
				<geometry>
					<cylinder>
						<length>0.001</length>
						<radius>0.04</radius>
					</cylinder>
				</geometry>
			</collision>
			<visual name="trochanter_2_visual">
				<pose frame=''>0 0.54 0 1.57 1.57 0</pose>
				<geometry>
					<cylinder>
						<length>0.001</length>
						<radius>0.04</radius>
					</cylinder>
				</geometry>
				<material>
					<ambient>0 1 0 0.6</ambient>
					<diffuse>0 1 0 0.6</diffuse>
				</material>
			</visual>
		</link>

		<link name="femur_2">
			<pose frame=''>0 0 0 0 0 0.785398</pose>
			<inertial>
				<pose frame=''>0 0.54 0 1.57 1.57 0</pose>
				<mass>5</mass>
				<inertia>
					<ixx>5</ixx>
					<ixy>0</ixy>
					<ixz>0</ixz>
					<iyy>5</iyy>
					<iyz>0</iyz>
					<izz>5</izz>
				</inertia>
			</inertial>
			<collision name="femur_2_collision">
				<pose frame=''>0 0.54 0 1.57 1.57 0</pose>
				<geometry>
					<cylinder>
						<length>0.48</length>
						<radius>0.04</radius>
					</cylinder>
				</geometry>
			</collision>
			<visual name="femur_2_visual">
				<pose frame=''>0 0.54 0 1.57 1.57 0</pose>
				<geometry>
					<cylinder>
						<length>0.48</length>
						<radius>0.04</radius>
					</cylinder>
				</geometry>
				<material>
					<ambient>0 1 0 0.6</ambient>
					<diffuse>0 1 0 0.6</diffuse>
				</material>
			</visual>
		</link>
		
		<link name="tibia_2">
			<pose frame=''>0 0 0 0 0 0.785398</pose>
			<inertial>
				<pose frame=''>0 1.02 0 1.57 1.57 0</pose>
				<mass>5</mass>
				<inertia>
					<ixx>5</ixx>
					<ixy>0</ixy>
					<ixz>0</ixz>
					<iyy>5</iyy>
					<iyz>0</iyz>
					<izz>5</izz>
				</inertia>
			</inertial>
			<collision name="tibia_2_collision">
				<pose frame=''>0 1.02 0 1.57 1.57 0</pose>
				<geometry>
					<cylinder>
						<length>0.48</length>
						<radius>0.04</radius>
					</cylinder>
				</geometry>
			</collision>
			<visual name="tibia_2_visual">
				<pose frame=''>0 1.02 0 1.57 1.57 0</pose>
				<geometry>
					<cylinder>
						<length>0.48</length>
						<radius>0.04</radius>
					</cylinder>
				</geometry>
				<material>
					<ambient>0 1 0 0.6</ambient>
					<diffuse>0 1 0 0.6</diffuse>
				</material>
			</visual>
		</link>
		
		<link name="tarsus_2">
			<pose frame=''>0 0 0 0 0 0.785398</pose>
			<inertial>
				<pose frame=''>0 1.5 0 1.57 1.57 0</pose>
				<mass>5</mass>
				<inertia>
					<ixx>5</ixx>
					<ixy>0</ixy>
					<ixz>0</ixz>
					<iyy>5</iyy>
					<iyz>0</iyz>
					<izz>5</izz>
				</inertia>
			</inertial>
			<collision name="tarsus_2_collision">
				<pose frame=''>0 1.5 0 1.57 1.57 0</pose>
				<geometry>
					<cylinder>
						<length>0.48</length>
						<radius>0.04</radius>
					</cylinder>
				</geometry>
			</collision>
			<visual name="tarsus_2_visual">
				<pose frame=''>0 1.5 0 1.57 1.57 0</pose>
				<geometry>
					<cylinder>
						<length>0.48</length>
						<radius>0.04</radius>
					</cylinder>
				</geometry>
				<material>
					<ambient>0 1 0 0.6</ambient>
					<diffuse>0 1 0 0.6</diffuse>
				</material>
			</visual>
		</link>
		
		<!-- Leg 2 joints -->
		
		<joint name="hip_2" type="revolute">
			<parent>body</parent>
			<child>trochanter_2</child>
			<pose frame=''>0 0.3 0 0 0 0</pose>
			<axis>
				<xyz>1 0 0</xyz>
				<limit>
					<lower>-0.9162979</lower>
					<upper>0.9162979</upper>
				</limit>
				<use_parent_model_frame>0</use_parent_model_frame>
			</axis>
		</joint>
		<joint name="hip2_2" type="revolute">
			<parent>trochanter_2</parent>
			<child>femur_2</child>
			<pose frame=''>0 0.3001 0 0 0 0</pose>
			<axis>
				<xyz>0 0 1</xyz>
				<limit>
					<lower>-0.610865</lower>
					<upper>0.610865</upper>
				</limit>
				<use_parent_model_frame>0</use_parent_model_frame>
			</axis>
		</joint>
		
		<joint name="knee_2" type="revolute">
			<parent>femur_2</parent>
			<child>tibia_2</child>
			<pose frame=''>0 0.78001 0 0 0 0</pose>
			<axis>
				<xyz>1 0 0</xyz>
				<limit>
					<lower>-0.349066</lower>
					<upper>2.44346</upper>
				</limit>
			</axis>
		</joint>
		
		<joint name="ankle_2" type="revolute">
			<parent>tibia_2</parent>
			<child>tarsus_2</child>
			<pose frame=''>0 1.26001 0 0 0 0</pose>
			<axis>
				<xyz>1 0 0</xyz>
				<limit>
					<lower>-1.090831</lower>
					<upper>1.090831</upper>
				</limit>
			</axis>
		</joint>

		<!-- Leg 3 links -->

		<!-- A temporary link, for the temporary solution of testing
		this file using revolute instead of universal joints -->
		<link name="trochanter_3">
			<pose frame=''>0 0 0 0 0 1.570796</pose>
			<inertial>
				<pose frame=''>0 0.54 0 1.57 1.57 0</pose>
				<mass>5</mass>
				<inertia>
					<ixx>5</ixx>
					<ixy>0</ixy>
					<ixz>0</ixz>
					<iyy>5</iyy>
					<iyz>0</iyz>
					<izz>5</izz>
				</inertia>
			</inertial>
			<collision name="trochanter_3_collision">
				<pose frame=''>0 0.54 0 1.57 1.57 0</pose>
				<geometry>
					<cylinder>
						<length>0.001</length>
						<radius>0.04</radius>
					</cylinder>
				</geometry>
			</collision>
			<visual name="trochanter_3_visual">
				<pose frame=''>0 0.54 0 1.57 1.57 0</pose>
				<geometry>
					<cylinder>
						<length>0.001</length>
						<radius>0.04</radius>
					</cylinder>
				</geometry>
				<material>
					<ambient>0 1 0 0.6</ambient>
					<diffuse>0 1 0 0.6</diffuse>
				</material>
			</visual>
		</link>
		
		<link name="femur_3">
			<pose frame=''>0 0 0 0 0 1.570796</pose>
			<inertial>
				<pose frame=''>0 0.54 0 1.57 1.57 0</pose>
				<mass>5</mass>
				<inertia>
					<ixx>5</ixx>
					<ixy>0</ixy>
					<ixz>0</ixz>
					<iyy>5</iyy>
					<iyz>0</iyz>
					<izz>5</izz>
				</inertia>
			</inertial>
			<collision name="femur_3_collision">
				<pose frame=''>0 0.54 0 1.57 1.57 0</pose>
				<geometry>
					<cylinder>
						<length>0.48</length>
						<radius>0.04</radius>
					</cylinder>
				</geometry>
			</collision>
			<visual name="femur_3_visual">
				<pose frame=''>0 0.54 0 1.57 1.57 0</pose>
				<geometry>
					<cylinder>
						<length>0.48</length>
						<radius>0.04</radius>
					</cylinder>
				</geometry>
				<material>
					<ambient>0 1 0 0.6</ambient>
					<diffuse>0 1 0 0.6</diffuse>
				</material>
			</visual>
		</link>
		
		<link name="tibia_3">
			<pose frame=''>0 0 0 0 0 1.570796</pose>
			<inertial>
				<pose frame=''>0 1.02 0 1.57 1.57 0</pose>
				<mass>5</mass>
				<inertia>
					<ixx>5</ixx>
					<ixy>0</ixy>
					<ixz>0</ixz>
					<iyy>5</iyy>
					<iyz>0</iyz>
					<izz>5</izz>
				</inertia>
			</inertial>
			<collision name="tibia_3_collision">
				<pose frame=''>0 1.02 0 1.57 1.57 0</pose>
				<geometry>
					<cylinder>
						<length>0.48</length>
						<radius>0.04</radius>
					</cylinder>
				</geometry>
			</collision>
			<visual name="tibia_3_visual">
				<pose frame=''>0 1.02 0 1.57 1.57 0</pose>
				<geometry>
					<cylinder>
						<length>0.48</length>
						<radius>0.04</radius>
					</cylinder>
				</geometry>
				<material>
					<ambient>0 1 0 0.6</ambient>
					<diffuse>0 1 0 0.6</diffuse>
				</material>
			</visual>
		</link>
		
		<link name="tarsus_3">
			<pose frame=''>0 0 0 0 0 1.570796</pose>
			<inertial>
				<pose frame=''>0 1.5 0 1.57 1.57 0</pose>
				<mass>5</mass>
				<inertia>
					<ixx>5</ixx>
					<ixy>0</ixy>
					<ixz>0</ixz>
					<iyy>5</iyy>
					<iyz>0</iyz>
					<izz>5</izz>
				</inertia>
			</inertial>
			<collision name="tarsus_3_collision">
				<pose frame=''>0 1.5 0 1.57 1.57 0</pose>
				<geometry>
					<cylinder>
						<length>0.48</length>
						<radius>0.04</radius>
					</cylinder>
				</geometry>
			</collision>
			<visual name="tarsus_3_visual">
				<pose frame=''>0 1.5 0 1.57 1.57 0</pose>
				<geometry>
					<cylinder>
						<length>0.48</length>
						<radius>0.04</radius>
					</cylinder>
				</geometry>
				<material>
					<ambient>0 1 0 0.6</ambient>
					<diffuse>0 1 0 0.6</diffuse>
				</material>
			</visual>
		</link>
		
		<!-- Leg 3 joints -->
		
		<joint name="hip_3" type="revolute">
			<parent>body</parent>
			<child>trochanter_3</child>
			<pose frame=''>0 0.3 0 0 0 0</pose>
			<axis>
				<xyz>1 0 0</xyz>
				<limit>
					<lower>-0.9162979</lower>
					<upper>0.9162979</upper>
				</limit>
				<use_parent_model_frame>0</use_parent_model_frame>
			</axis>
		</joint>
		<joint name="hip2_3" type="revolute">
			<parent>trochanter_3</parent>
			<child>femur_3</child>
			<pose frame=''>0 0.3001 0 0 0 0</pose>
			<axis>
				<xyz>0 0 1</xyz>
				<limit>
					<lower>-0.610865</lower>
					<upper>0.610865</upper>
				</limit>
				<use_parent_model_frame>0</use_parent_model_frame>
			</axis>
		</joint>
		
		<joint name="knee_3" type="revolute">
			<parent>femur_3</parent>
			<child>tibia_3</child>
			<pose frame=''>0 0.78001 0 0 0 0</pose>
			<axis>
				<xyz>1 0 0</xyz>
				<limit>
					<lower>-0.349066</lower>
					<upper>2.44346</upper>
				</limit>
			</axis>
		</joint>
		
		<joint name="ankle_3" type="revolute">
			<parent>tibia_3</parent>
			<child>tarsus_3</child>
			<pose frame=''>0 1.26001 0 0 0 0</pose>
			<axis>
				<xyz>1 0 0</xyz>
				<limit>
					<lower>-1.090831</lower>
					<upper>1.090831</upper>
				</limit>
			</axis>
		</joint>

		<!-- Leg 4 links -->

		<!-- A temporary link, for the temporary solution of testing
		this file using revolute instead of universal joints -->
		<link name="trochanter_4">
			<pose frame=''>0 0 0 0 0 2.356194</pose>
			<inertial>
				<pose frame=''>0 0.54 0 1.57 1.57 0</pose>
				<mass>5</mass>
				<inertia>
					<ixx>5</ixx>
					<ixy>0</ixy>
					<ixz>0</ixz>
					<iyy>5</iyy>
					<iyz>0</iyz>
					<izz>5</izz>
				</inertia>
			</inertial>
			<collision name="trochanter_4_collision">
				<pose frame=''>0 0.54 0 1.57 1.57 0</pose>
				<geometry>
					<cylinder>
						<length>0.001</length>
						<radius>0.04</radius>
					</cylinder>
				</geometry>
			</collision>
			<visual name="trochanter_4_visual">
				<pose frame=''>0 0.54 0 1.57 1.57 0</pose>
				<geometry>
					<cylinder>
						<length>0.001</length>
						<radius>0.04</radius>
					</cylinder>
				</geometry>
				<material>
					<ambient>0 1 0 0.6</ambient>
					<diffuse>0 1 0 0.6</diffuse>
				</material>
			</visual>
		</link>
		
		<link name="femur_4">
			<pose frame=''>0 0 0 0 0 2.356194</pose>
			<inertial>
				<pose frame=''>0 0.54 0 1.57 1.57 0</pose>
				<mass>5</mass>
				<inertia>
					<ixx>5</ixx>
					<ixy>0</ixy>
					<ixz>0</ixz>
					<iyy>5</iyy>
					<iyz>0</iyz>
					<izz>5</izz>
				</inertia>
			</inertial>
			<collision name="femur_4_collision">
				<pose frame=''>0 0.54 0 1.57 1.57 0</pose>
				<geometry>
					<cylinder>
						<length>0.48</length>
						<radius>0.04</radius>
					</cylinder>
				</geometry>
			</collision>
			<visual name="femur_4_visual">
				<pose frame=''>0 0.54 0 1.57 1.57 0</pose>
				<geometry>
					<cylinder>
						<length>0.48</length>
						<radius>0.04</radius>
					</cylinder>
				</geometry>
				<material>
					<ambient>0 1 0 0.6</ambient>
					<diffuse>0 1 0 0.6</diffuse>
				</material>
			</visual>
		</link>
		
		<link name="tibia_4">
			<pose frame=''>0 0 0 0 0 2.356194</pose>
			<inertial>
				<pose frame=''>0 1.02 0 1.57 1.57 0</pose>
				<mass>5</mass>
				<inertia>
					<ixx>5</ixx>
					<ixy>0</ixy>
					<ixz>0</ixz>
					<iyy>5</iyy>
					<iyz>0</iyz>
					<izz>5</izz>
				</inertia>
			</inertial>
			<collision name="tibia_4_collision">
				<pose frame=''>0 1.02 0 1.57 1.57 0</pose>
				<geometry>
					<cylinder>
						<length>0.48</length>
						<radius>0.04</radius>
					</cylinder>
				</geometry>
			</collision>
			<visual name="tibia_4_visual">
				<pose frame=''>0 1.02 0 1.57 1.57 0</pose>
				<geometry>
					<cylinder>
						<length>0.48</length>
						<radius>0.04</radius>
					</cylinder>
				</geometry>
				<material>
					<ambient>0 1 0 0.6</ambient>
					<diffuse>0 1 0 0.6</diffuse>
				</material>
			</visual>
		</link>
		
		<link name="tarsus_4">
			<pose frame=''>0 0 0 0 0 2.356194</pose>
			<inertial>
				<pose frame=''>0 1.5 0 1.57 1.57 0</pose>
				<mass>5</mass>
				<inertia>
					<ixx>5</ixx>
					<ixy>0</ixy>
					<ixz>0</ixz>
					<iyy>5</iyy>
					<iyz>0</iyz>
					<izz>5</izz>
				</inertia>
			</inertial>
			<collision name="tarsus_4_collision">
				<pose frame=''>0 1.5 0 1.57 1.57 0</pose>
				<geometry>
					<cylinder>
						<length>0.48</length>
						<radius>0.04</radius>
					</cylinder>
				</geometry>
			</collision>
			<visual name="tarsus_4_visual">
				<pose frame=''>0 1.5 0 1.57 1.57 0</pose>
				<geometry>
					<cylinder>
						<length>0.48</length>
						<radius>0.04</radius>
					</cylinder>
				</geometry>
				<material>
					<ambient>0 1 0 0.6</ambient>
					<diffuse>0 1 0 0.6</diffuse>
				</material>
			</visual>
		</link>
		
		<!-- Leg 4 joints -->
		
		<joint name="hip_4" type="revolute">
			<parent>body</parent>
			<child>trochanter_4</child>
			<pose frame=''>0 0.3 0 0 0 0</pose>
			<axis>
				<xyz>1 0 0</xyz>
				<limit>
					<lower>-0.9162979</lower>
					<upper>0.9162979</upper>
				</limit>
				<use_parent_model_frame>0</use_parent_model_frame>
			</axis>
		</joint>
		<joint name="hip2_4" type="revolute">
			<parent>trochanter_4</parent>
			<child>femur_4</child>
			<pose frame=''>0 0.3001 0 0 0 0</pose>
			<axis>
				<xyz>0 0 1</xyz>
				<limit>
					<lower>-0.610865</lower>
					<upper>0.610865</upper>
				</limit>
				<use_parent_model_frame>0</use_parent_model_frame>
			</axis>
		</joint>
		
		<joint name="knee_4" type="revolute">
			<parent>femur_4</parent>
			<child>tibia_4</child>
			<pose frame=''>0 0.78001 0 0 0 0</pose>
			<axis>
				<xyz>1 0 0</xyz>
				<limit>
					<lower>-0.349066</lower>
					<upper>2.44346</upper>
				</limit>
			</axis>
		</joint>
		
		<joint name="ankle_4" type="revolute">
			<parent>tibia_4</parent>
			<child>tarsus_4</child>
			<pose frame=''>0 1.26001 0 0 0 0</pose>
			<axis>
				<xyz>1 0 0</xyz>
				<limit>
					<lower>-1.090831</lower>
					<upper>1.090831</upper>
				</limit>
			</axis>
		</joint>

		<!-- Leg 5 links -->

		<!-- A temporary link, for the temporary solution of testing
		this file using revolute instead of universal joints -->
		<link name="trochanter_5">
			<pose frame=''>0 0 0 0 0 3.141592</pose>
			<inertial>
				<pose frame=''>0 0.54 0 1.57 1.57 0</pose>
				<mass>5</mass>
				<inertia>
					<ixx>5</ixx>
					<ixy>0</ixy>
					<ixz>0</ixz>
					<iyy>5</iyy>
					<iyz>0</iyz>
					<izz>5</izz>
				</inertia>
			</inertial>
			<collision name="trochanter_5_collision">
				<pose frame=''>0 0.54 0 1.57 1.57 0</pose>
				<geometry>
					<cylinder>
						<length>0.001</length>
						<radius>0.04</radius>
					</cylinder>
				</geometry>
			</collision>
			<visual name="trochanter_5_visual">
				<pose frame=''>0 0.54 0 1.57 1.57 0</pose>
				<geometry>
					<cylinder>
						<length>0.001</length>
						<radius>0.04</radius>
					</cylinder>
				</geometry>
				<material>
					<ambient>0 1 0 0.6</ambient>
					<diffuse>0 1 0 0.6</diffuse>
				</material>
			</visual>
		</link>
		
		<link name="femur_5">
			<pose frame=''>0 0 0 0 0 3.141592</pose>
			<inertial>
				<pose frame=''>0 0.54 0 1.57 1.57 0</pose>
				<mass>5</mass>
				<inertia>
					<ixx>5</ixx>
					<ixy>0</ixy>
					<ixz>0</ixz>
					<iyy>5</iyy>
					<iyz>0</iyz>
					<izz>5</izz>
				</inertia>
			</inertial>
			<collision name="femur_5_collision">
				<pose frame=''>0 0.54 0 1.57 1.57 0</pose>
				<geometry>
					<cylinder>
						<length>0.48</length>
						<radius>0.04</radius>
					</cylinder>
				</geometry>
			</collision>
			<visual name="femur_5_visual">
				<pose frame=''>0 0.54 0 1.57 1.57 0</pose>
				<geometry>
					<cylinder>
						<length>0.48</length>
						<radius>0.04</radius>
					</cylinder>
				</geometry>
				<material>
					<ambient>0 1 0 0.6</ambient>
					<diffuse>0 1 0 0.6</diffuse>
				</material>
			</visual>
		</link>
		
		<link name="tibia_5">
			<pose frame=''>0 0 0 0 0 3.141592</pose>
			<inertial>
				<pose frame=''>0 1.02 0 1.57 1.57 0</pose>
				<mass>5</mass>
				<inertia>
					<ixx>5</ixx>
					<ixy>0</ixy>
					<ixz>0</ixz>
					<iyy>5</iyy>
					<iyz>0</iyz>
					<izz>5</izz>
				</inertia>
			</inertial>
			<collision name="tibia_5_collision">
				<pose frame=''>0 1.02 0 1.57 1.57 0</pose>
				<geometry>
					<cylinder>
						<length>0.48</length>
						<radius>0.04</radius>
					</cylinder>
				</geometry>
			</collision>
			<visual name="tibia_5_visual">
				<pose frame=''>0 1.02 0 1.57 1.57 0</pose>
				<geometry>
					<cylinder>
						<length>0.48</length>
						<radius>0.04</radius>
					</cylinder>
				</geometry>
				<material>
					<ambient>0 1 0 0.6</ambient>
					<diffuse>0 1 0 0.6</diffuse>
				</material>
			</visual>
		</link>
		
		<link name="tarsus_5">
			<pose frame=''>0 0 0 0 0 3.141592</pose>
			<inertial>
				<pose frame=''>0 1.5 0 1.57 1.57 0</pose>
				<mass>5</mass>
				<inertia>
					<ixx>5</ixx>
					<ixy>0</ixy>
					<ixz>0</ixz>
					<iyy>5</iyy>
					<iyz>0</iyz>
					<izz>5</izz>
				</inertia>
			</inertial>
			<collision name="tarsus_5_collision">
				<pose frame=''>0 1.5 0 1.57 1.57 0</pose>
				<geometry>
					<cylinder>
						<length>0.48</length>
						<radius>0.04</radius>
					</cylinder>
				</geometry>
			</collision>
			<visual name="tarsus_5_visual">
				<pose frame=''>0 1.5 0 1.57 1.57 0</pose>
				<geometry>
					<cylinder>
						<length>0.48</length>
						<radius>0.04</radius>
					</cylinder>
				</geometry>
				<material>
					<ambient>0 1 0 0.6</ambient>
					<diffuse>0 1 0 0.6</diffuse>
				</material>
			</visual>
		</link>
		
		<!-- Leg 5 joints -->
		
		<joint name="hip_5" type="revolute">
			<parent>body</parent>
			<child>trochanter_5</child>
			<pose frame=''>0 0.3 0 0 0 0</pose>
			<axis>
				<xyz>1 0 0</xyz>
				<limit>
					<lower>-0.9162979</lower>
					<upper>0.9162979</upper>
				</limit>
				<use_parent_model_frame>0</use_parent_model_frame>
			</axis>
		</joint>
		<joint name="hip2_5" type="revolute">
			<parent>trochanter_5</parent>
			<child>femur_5</child>
			<pose frame=''>0 0.3001 0 0 0 0</pose>
			<axis>
				<xyz>0 0 1</xyz>
				<limit>
					<lower>-0.610865</lower>
					<upper>0.610865</upper>
				</limit>
				<use_parent_model_frame>0</use_parent_model_frame>
			</axis>
		</joint>
		
		<joint name="knee_5" type="revolute">
			<parent>femur_5</parent>
			<child>tibia_5</child>
			<pose frame=''>0 0.78001 0 0 0 0</pose>
			<axis>
				<xyz>1 0 0</xyz>
				<limit>
					<lower>-0.349066</lower>
					<upper>2.44346</upper>
				</limit>
			</axis>
		</joint>
		
		<joint name="ankle_5" type="revolute">
			<parent>tibia_5</parent>
			<child>tarsus_5</child>
			<pose frame=''>0 1.26001 0 0 0 0</pose>
			<axis>
				<xyz>1 0 0</xyz>
				<limit>
					<lower>-1.090831</lower>
					<upper>1.090831</upper>
				</limit>
			</axis>
		</joint>

		<!-- Leg 6 links -->

		<!-- A temporary link, for the temporary solution of testing
		this file using revolute instead of universal joints -->
		<link name="trochanter_6">
			<pose frame=''>0 0 0 0 0 3.92699</pose>
			<inertial>
				<pose frame=''>0 0.54 0 1.57 1.57 0</pose>
				<mass>5</mass>
				<inertia>
					<ixx>5</ixx>
					<ixy>0</ixy>
					<ixz>0</ixz>
					<iyy>5</iyy>
					<iyz>0</iyz>
					<izz>5</izz>
				</inertia>
			</inertial>
			<collision name="trochanter_6_collision">
				<pose frame=''>0 0.54 0 1.57 1.57 0</pose>
				<geometry>
					<cylinder>
						<length>0.001</length>
						<radius>0.04</radius>
					</cylinder>
				</geometry>
			</collision>
			<visual name="trochanter_6_visual">
				<pose frame=''>0 0.54 0 1.57 1.57 0</pose>
				<geometry>
					<cylinder>
						<length>0.001</length>
						<radius>0.04</radius>
					</cylinder>
				</geometry>
				<material>
					<ambient>0 1 0 0.6</ambient>
					<diffuse>0 1 0 0.6</diffuse>
				</material>
			</visual>
		</link>
		
		<link name="femur_6">
			<pose frame=''>0 0 0 0 0 3.92699</pose>
			<inertial>
				<pose frame=''>0 0.54 0 1.57 1.57 0</pose>
				<mass>5</mass>
				<inertia>
					<ixx>5</ixx>
					<ixy>0</ixy>
					<ixz>0</ixz>
					<iyy>5</iyy>
					<iyz>0</iyz>
					<izz>5</izz>
				</inertia>
			</inertial>
			<collision name="femur_6_collision">
				<pose frame=''>0 0.54 0 1.57 1.57 0</pose>
				<geometry>
					<cylinder>
						<length>0.48</length>
						<radius>0.04</radius>
					</cylinder>
				</geometry>
			</collision>
			<visual name="femur_6_visual">
				<pose frame=''>0 0.54 0 1.57 1.57 0</pose>
				<geometry>
					<cylinder>
						<length>0.48</length>
						<radius>0.04</radius>
					</cylinder>
				</geometry>
				<material>
					<ambient>0 1 0 0.6</ambient>
					<diffuse>0 1 0 0.6</diffuse>
				</material>
			</visual>
		</link>
		
		<link name="tibia_6">
			<pose frame=''>0 0 0 0 0 3.92699</pose>
			<inertial>
				<pose frame=''>0 1.02 0 1.57 1.57 0</pose>
				<mass>5</mass>
				<inertia>
					<ixx>5</ixx>
					<ixy>0</ixy>
					<ixz>0</ixz>
					<iyy>5</iyy>
					<iyz>0</iyz>
					<izz>5</izz>
				</inertia>
			</inertial>
			<collision name="tibia_6_collision">
				<pose frame=''>0 1.02 0 1.57 1.57 0</pose>
				<geometry>
					<cylinder>
						<length>0.48</length>
						<radius>0.04</radius>
					</cylinder>
				</geometry>
			</collision>
			<visual name="tibia_6_visual">
				<pose frame=''>0 1.02 0 1.57 1.57 0</pose>
				<geometry>
					<cylinder>
						<length>0.48</length>
						<radius>0.04</radius>
					</cylinder>
				</geometry>
				<material>
					<ambient>0 1 0 0.6</ambient>
					<diffuse>0 1 0 0.6</diffuse>
				</material>
			</visual>
		</link>
		
		<link name="tarsus_6">
			<pose frame=''>0 0 0 0 0 3.92699</pose>
			<inertial>
				<pose frame=''>0 1.5 0 1.57 1.57 0</pose>
				<mass>5</mass>
				<inertia>
					<ixx>5</ixx>
					<ixy>0</ixy>
					<ixz>0</ixz>
					<iyy>5</iyy>
					<iyz>0</iyz>
					<izz>5</izz>
				</inertia>
			</inertial>
			<collision name="tarsus_6_collision">
				<pose frame=''>0 1.5 0 1.57 1.57 0</pose>
				<geometry>
					<cylinder>
						<length>0.48</length>
						<radius>0.04</radius>
					</cylinder>
				</geometry>
			</collision>
			<visual name="tarsus_6_visual">
				<pose frame=''>0 1.5 0 1.57 1.57 0</pose>
				<geometry>
					<cylinder>
						<length>0.48</length>
						<radius>0.04</radius>
					</cylinder>
				</geometry>
				<material>
					<ambient>0 1 0 0.6</ambient>
					<diffuse>0 1 0 0.6</diffuse>
				</material>
			</visual>
		</link>
		
		<!-- Leg 6 joints -->
		
		<joint name="hip_6" type="revolute">
			<parent>body</parent>
			<child>trochanter_6</child>
			<pose frame=''>0 0.3 0 0 0 0</pose>
			<axis>
				<xyz>1 0 0</xyz>
				<limit>
					<lower>-0.9162979</lower>
					<upper>0.9162979</upper>
				</limit>
				<use_parent_model_frame>0</use_parent_model_frame>
			</axis>
		</joint>
		<joint name="hip2_6" type="revolute">
			<parent>trochanter_6</parent>
			<child>femur_6</child>
			<pose frame=''>0 0.3001 0 0 0 0</pose>
			<axis>
				<xyz>0 0 1</xyz>
				<limit>
					<lower>-0.610865</lower>
					<upper>0.610865</upper>
				</limit>
				<use_parent_model_frame>0</use_parent_model_frame>
			</axis>
		</joint>
		
		<joint name="knee_6" type="revolute">
			<parent>femur_6</parent>
			<child>tibia_6</child>
			<pose frame=''>0 0.78001 0 0 0 0</pose>
			<axis>
				<xyz>1 0 0</xyz>
				<limit>
					<lower>-0.349066</lower>
					<upper>2.44346</upper>
				</limit>
			</axis>
		</joint>
		
		<joint name="ankle_6" type="revolute">
			<parent>tibia_6</parent>
			<child>tarsus_6</child>
			<pose frame=''>0 1.26001 0 0 0 0</pose>
			<axis>
				<xyz>1 0 0</xyz>
				<limit>
					<lower>-1.090831</lower>
					<upper>1.090831</upper>
				</limit>
			</axis>
		</joint>

		<!-- Leg 7 links -->

		<!-- A temporary link, for the temporary solution of testing
		this file using revolute instead of universal joints -->
		<link name="trochanter_7">
			<pose frame=''>0 0 0 0 0 4.712388</pose>
			<inertial>
				<pose frame=''>0 0.54 0 1.57 1.57 0</pose>
				<mass>5</mass>
				<inertia>
					<ixx>5</ixx>
					<ixy>0</ixy>
					<ixz>0</ixz>
					<iyy>5</iyy>
					<iyz>0</iyz>
					<izz>5</izz>
				</inertia>
			</inertial>
			<collision name="trochanter_7_collision">
				<pose frame=''>0 0.54 0 1.57 1.57 0</pose>
				<geometry>
					<cylinder>
						<length>0.001</length>
						<radius>0.04</radius>
					</cylinder>
				</geometry>
			</collision>
			<visual name="trochanter_7_visual">
				<pose frame=''>0 0.54 0 1.57 1.57 0</pose>
				<geometry>
					<cylinder>
						<length>0.001</length>
						<radius>0.04</radius>
					</cylinder>
				</geometry>
				<material>
					<ambient>0 1 0 0.6</ambient>
					<diffuse>0 1 0 0.6</diffuse>
				</material>
			</visual>
		</link>
		
		<link name="femur_7">
			<pose frame=''>0 0 0 0 0 4.712388</pose>
			<inertial>
				<pose frame=''>0 0.54 0 1.57 1.57 0</pose>
				<mass>5</mass>
				<inertia>
					<ixx>5</ixx>
					<ixy>0</ixy>
					<ixz>0</ixz>
					<iyy>5</iyy>
					<iyz>0</iyz>
					<izz>5</izz>
				</inertia>
			</inertial>
			<collision name="femur_7_collision">
				<pose frame=''>0 0.54 0 1.57 1.57 0</pose>
				<geometry>
					<cylinder>
						<length>0.48</length>
						<radius>0.04</radius>
					</cylinder>
				</geometry>
			</collision>
			<visual name="femur_7_visual">
				<pose frame=''>0 0.54 0 1.57 1.57 0</pose>
				<geometry>
					<cylinder>
						<length>0.48</length>
						<radius>0.04</radius>
					</cylinder>
				</geometry>
				<material>
					<ambient>0 1 0 0.6</ambient>
					<diffuse>0 1 0 0.6</diffuse>
				</material>
			</visual>
		</link>
		
		<link name="tibia_7">
			<pose frame=''>0 0 0 0 0 4.712388</pose>
			<inertial>
				<pose frame=''>0 1.02 0 1.57 1.57 0</pose>
				<mass>5</mass>
				<inertia>
					<ixx>5</ixx>
					<ixy>0</ixy>
					<ixz>0</ixz>
					<iyy>5</iyy>
					<iyz>0</iyz>
					<izz>5</izz>
				</inertia>
			</inertial>
			<collision name="tibia_7_collision">
				<pose frame=''>0 1.02 0 1.57 1.57 0</pose>
				<geometry>
					<cylinder>
						<length>0.48</length>
						<radius>0.04</radius>
					</cylinder>
				</geometry>
			</collision>
			<visual name="tibia_7_visual">
				<pose frame=''>0 1.02 0 1.57 1.57 0</pose>
				<geometry>
					<cylinder>
						<length>0.48</length>
						<radius>0.04</radius>
					</cylinder>
				</geometry>
				<material>
					<ambient>0 1 0 0.6</ambient>
					<diffuse>0 1 0 0.6</diffuse>
				</material>
			</visual>
		</link>
		
		<link name="tarsus_7">
			<pose frame=''>0 0 0 0 0 4.712388</pose>
			<inertial>
				<pose frame=''>0 1.5 0 1.57 1.57 0</pose>
				<mass>5</mass>
				<inertia>
					<ixx>5</ixx>
					<ixy>0</ixy>
					<ixz>0</ixz>
					<iyy>5</iyy>
					<iyz>0</iyz>
					<izz>5</izz>
				</inertia>
			</inertial>
			<collision name="tarsus_7_collision">
				<pose frame=''>0 1.5 0 1.57 1.57 0</pose>
				<geometry>
					<cylinder>
						<length>0.48</length>
						<radius>0.04</radius>
					</cylinder>
				</geometry>
			</collision>
			<visual name="tarsus_7_visual">
				<pose frame=''>0 1.5 0 1.57 1.57 0</pose>
				<geometry>
					<cylinder>
						<length>0.48</length>
						<radius>0.04</radius>
					</cylinder>
				</geometry>
				<material>
					<ambient>0 1 0 0.6</ambient>
					<diffuse>0 1 0 0.6</diffuse>
				</material>
			</visual>
		</link>
		
		<!-- Leg 7 joints -->
		
		<joint name="hip_7" type="revolute">
			<parent>body</parent>
			<child>trochanter_7</child>
			<pose frame=''>0 0.3 0 0 0 0</pose>
			<axis>
				<xyz>1 0 0</xyz>
				<limit>
					<lower>-0.9162979</lower>
					<upper>0.9162979</upper>
				</limit>
				<use_parent_model_frame>0</use_parent_model_frame>
			</axis>
		</joint>
		<joint name="hip2_7" type="revolute">
			<parent>trochanter_7</parent>
			<child>femur_7</child>
			<pose frame=''>0 0.3001 0 0 0 0</pose>
			<axis>
				<xyz>0 0 1</xyz>
				<limit>
					<lower>-0.610865</lower>
					<upper>0.610865</upper>
				</limit>
				<use_parent_model_frame>0</use_parent_model_frame>
			</axis>
		</joint>
		
		<joint name="knee_7" type="revolute">
			<parent>femur_7</parent>
			<child>tibia_7</child>
			<pose frame=''>0 0.78001 0 0 0 0</pose>
			<axis>
				<xyz>1 0 0</xyz>
				<limit>
					<lower>-0.349066</lower>
					<upper>2.44346</upper>
				</limit>
			</axis>
		</joint>
		
		<joint name="ankle_7" type="revolute">
			<parent>tibia_7</parent>
			<child>tarsus_7</child>
			<pose frame=''>0 1.26001 0 0 0 0</pose>
			<axis>
				<xyz>1 0 0</xyz>
				<limit>
					<lower>-1.090831</lower>
					<upper>1.090831</upper>
				</limit>
			</axis>
		</joint>

		<!-- Leg 8 links -->

		<!-- A temporary link, for the temporary solution of testing
		this file using revolute instead of universal joints -->
		<link name="trochanter_8">
			<pose frame=''>0 0 0 0 0 5.497786</pose>
			<inertial>
				<pose frame=''>0 0.54 0 1.57 1.57 0</pose>
				<mass>5</mass>
				<inertia>
					<ixx>5</ixx>
					<ixy>0</ixy>
					<ixz>0</ixz>
					<iyy>5</iyy>
					<iyz>0</iyz>
					<izz>5</izz>
				</inertia>
			</inertial>
			<collision name="trochanter_8_collision">
				<pose frame=''>0 0.54 0 1.57 1.57 0</pose>
				<geometry>
					<cylinder>
						<length>0.001</length>
						<radius>0.04</radius>
					</cylinder>
				</geometry>
			</collision>
			<visual name="trochanter_8_visual">
				<pose frame=''>0 0.54 0 1.57 1.57 0</pose>
				<geometry>
					<cylinder>
						<length>0.001</length>
						<radius>0.04</radius>
					</cylinder>
				</geometry>
				<material>
					<ambient>0 1 0 0.6</ambient>
					<diffuse>0 1 0 0.6</diffuse>
				</material>
			</visual>
		</link>
		
		<link name="femur_8">
			<pose frame=''>0 0 0 0 0 5.497786</pose>
			<inertial>
				<pose frame=''>0 0.54 0 1.57 1.57 0</pose>
				<mass>5</mass>
				<inertia>
					<ixx>5</ixx>
					<ixy>0</ixy>
					<ixz>0</ixz>
					<iyy>5</iyy>
					<iyz>0</iyz>
					<izz>5</izz>
				</inertia>
			</inertial>
			<collision name="femur_8_collision">
				<pose frame=''>0 0.54 0 1.57 1.57 0</pose>
				<geometry>
					<cylinder>
						<length>0.48</length>
						<radius>0.04</radius>
					</cylinder>
				</geometry>
			</collision>
			<visual name="femur_8_visual">
				<pose frame=''>0 0.54 0 1.57 1.57 0</pose>
				<geometry>
					<cylinder>
						<length>0.48</length>
						<radius>0.04</radius>
					</cylinder>
				</geometry>
				<material>
					<ambient>0 1 0 0.6</ambient>
					<diffuse>0 1 0 0.6</diffuse>
				</material>
			</visual>
		</link>
		
		<link name="tibia_8">
			<pose frame=''>0 0 0 0 0 5.497786</pose>
			<inertial>
				<pose frame=''>0 1.02 0 1.57 1.57 0</pose>
				<mass>5</mass>
				<inertia>
					<ixx>5</ixx>
					<ixy>0</ixy>
					<ixz>0</ixz>
					<iyy>5</iyy>
					<iyz>0</iyz>
					<izz>5</izz>
				</inertia>
			</inertial>
			<collision name="tibia_8_collision">
				<pose frame=''>0 1.02 0 1.57 1.57 0</pose>
				<geometry>
					<cylinder>
						<length>0.48</length>
						<radius>0.04</radius>
					</cylinder>
				</geometry>
			</collision>
			<visual name="tibia_8_visual">
				<pose frame=''>0 1.02 0 1.57 1.57 0</pose>
				<geometry>
					<cylinder>
						<length>0.48</length>
						<radius>0.04</radius>
					</cylinder>
				</geometry>
				<material>
					<ambient>0 1 0 0.6</ambient>
					<diffuse>0 1 0 0.6</diffuse>
				</material>
			</visual>
		</link>
		
		<link name="tarsus_8">
			<pose frame=''>0 0 0 0 0 5.497786</pose>
			<inertial>
				<pose frame=''>0 1.5 0 1.57 1.57 0</pose>
				<mass>5</mass>
				<inertia>
					<ixx>5</ixx>
					<ixy>0</ixy>
					<ixz>0</ixz>
					<iyy>5</iyy>
					<iyz>0</iyz>
					<izz>5</izz>
				</inertia>
			</inertial>
			<collision name="tarsus_8_collision">
				<pose frame=''>0 1.5 0 1.57 1.57 0</pose>
				<geometry>
					<cylinder>
						<length>0.48</length>
						<radius>0.04</radius>
					</cylinder>
				</geometry>
			</collision>
			<visual name="tarsus_8_visual">
				<pose frame=''>0 1.5 0 1.57 1.57 0</pose>
				<geometry>
					<cylinder>
						<length>0.48</length>
						<radius>0.04</radius>
					</cylinder>
				</geometry>
				<material>
					<ambient>0 1 0 0.6</ambient>
					<diffuse>0 1 0 0.6</diffuse>
				</material>
			</visual>
		</link>
		
		<!-- Leg 8 joints -->

		<joint name="hip_8" type="revolute">
			<parent>body</parent>
			<child>trochanter_8</child>
			<pose frame=''>0 0.3 0 0 0 0</pose>
			<axis>
				<xyz>1 0 0</xyz>
				<limit>
					<lower>-0.9162979</lower>
					<upper>0.9162979</upper>
				</limit>
				<use_parent_model_frame>0</use_parent_model_frame>
			</axis>
		</joint>
		<joint name="hip2_8" type="revolute">
			<parent>trochanter_8</parent>
			<child>femur_8</child>
			<pose frame=''>0 0.3001 0 0 0 0</pose>
			<axis>
				<xyz>0 0 1</xyz>
				<limit>
					<lower>-0.610865</lower>
					<upper>0.610865</upper>
				</limit>
				<use_parent_model_frame>0</use_parent_model_frame>
			</axis>
		</joint>
		
		<joint name="knee_8" type="revolute">
			<parent>femur_8</parent>
			<child>tibia_8</child>
			<pose frame=''>0 0.78001 0 0 0 0</pose>
			<axis>
				<xyz>1 0 0</xyz>
				<limit>
					<lower>-0.349066</lower>
					<upper>2.44346</upper>
				</limit>
			</axis>
		</joint>
		
		<joint name="ankle_8" type="revolute">
			<parent>tibia_8</parent>
			<child>tarsus_8</child>
			<pose frame=''>0 1.26001 0 0 0 0</pose>
			<axis>
				<xyz>1 0 0</xyz>
				<limit>
					<lower>-1.090831</lower>
					<upper>1.090831</upper>
				</limit>
			</axis>
		</joint>

	</model>
</world>
</sdf>
