<?xml version='1.0'?>
<sdf version='1.6'>
<world name='default'>
	<model name="spider">

		<!-- Prevents the robot from falling through the world when visualized in Gazebo. -->	
		<joint name="body2world" type="fixed">
			<parent>world</parent>
			<child>body</child>
		</joint>

		<!-- Floating base link -->
		
		<link name="body">
			<pose>0 0 0 0 0 0</pose>
			<inertial>
				<mass>1.57</mass>
				<inertia>
					<ixx>0.13083</ixx>
					<ixy>0</ixy>
					<ixz>0</ixz>
					<iyy>0</iyy>
					<iyz>0</iyz>
					<izz>0.13083</izz>
				</inertia>
			</inertial>
			<collision name="body_collision">
			    <pose>0 0 0 1.57 1.57 0 </pose>
				<geometry>
					<cylinder>
						<length>1</length>
						<radius>0.2</radius>
					</cylinder>
				</geometry>
			</collision>
			<visual name="abdomen_1">
		    	<pose>0 -0.2 0 0 0 0</pose>
				<geometry>
					<sphere>
						<radius>0.2</radius>
					</sphere>
				</geometry>
				<material>
				    <ambient>0.88 0.45 0.08 1</ambient>
					<diffuse>0.88 0.45 0.08 1</diffuse>
				</material>
			</visual>
			<visual name="abdomen_2">
		    	<pose>0 -0.27 0 1.57 1.57 0</pose>
				<geometry>
					<cylinder>
					    <length>0.14</length>
						<radius>0.2</radius>
					</cylinder>
				</geometry>
				<material>
				    <ambient>0.88 0.45 0.08 1</ambient>
					<diffuse>0.88 0.45 0.08 1</diffuse>
				</material>
			</visual>
			<visual name="abdomen_3">
		    	<pose>0 -0.34 0 0 0 0</pose>
				<geometry>
					<sphere>
						<radius>0.2</radius>
					</sphere>
				</geometry>
				<material>
				    <ambient>0.88 0.45 0.08 1</ambient>
					<diffuse>0.88 0.45 0.08 1</diffuse>
				</material>
			</visual>
			<visual name="thorax_1">
		    	<pose>0 0.175 0 0 0 0</pose>
				<geometry>
					<sphere>
						<radius>0.175</radius>
					</sphere>
				</geometry>
				<material>
				    <ambient>0.57 0.26 0.027 1</ambient>
					<diffuse>0.57 0.26 0.027 1</diffuse>
				</material>
			</visual>
			<visual name="thorax_2">
		    	<pose>0 0.2 0 1.57 1.57 0</pose>
				<geometry>
					<cylinder>
					    <length>0.048</length>
						<radius>0.175</radius>
					</cylinder>
				</geometry>
				<material>
				    <ambient>0.88 0.45 0.08 1</ambient>
					<diffuse>0.88 0.45 0.08 1</diffuse>
				</material>
			</visual>
			<visual name="thorax_3">
		    	<pose>0 0.223 0 0 0 0</pose>
				<geometry>
					<sphere>
						<radius>0.175</radius>
					</sphere>
				</geometry>
				<material>
				    <ambient>0.57 0.26 0.027 1</ambient>
					<diffuse>0.57 0.26 0.027 1</diffuse>
				</material>
			</visual>
			<visual name="chelicera_1">
		    	<pose>-0.05 0.398 0 0 0 0</pose>
				<geometry>
					<sphere>
						<radius>0.05</radius>
					</sphere>
				</geometry>
				<material>
				    <ambient>0.88 0.45 0.08 1</ambient>
					<diffuse>0.88 0.45 0.08 1</diffuse>
				</material>
			</visual>
			<visual name="chelicera_2">
		    	<pose>0.05 0.398 0 0 0 0</pose>
				<geometry>
					<sphere>
						<radius>0.05</radius>
					</sphere>
				</geometry>
				<material>
				    <ambient>0.88 0.45 0.08 1</ambient>
					<diffuse>0.88 0.45 0.08 1</diffuse>
				</material>
			</visual>
			<visual name="pedipalp_left_1">
		    	<pose>-0.1 0.398 0 1.57 1.57 0.4</pose>
				<geometry>
					<cylinder>
					    <length>0.2</length>
						<radius>0.02</radius>
					</cylinder>
				</geometry>
				<material>
				    <ambient>0.88 0.45 0.08 1</ambient>
					<diffuse>0.88 0.45 0.08 1</diffuse>
				</material>
			</visual>
			<visual name="pedipalp_left_2">
		    	<pose>-0.1 0.57 0 1.57 1.57 -0.4</pose>
				<geometry>
					<cylinder>
					    <length>0.2</length>
						<radius>0.02</radius>
					</cylinder>
				</geometry>
				<material>
				    <ambient>0.88 0.45 0.08 1</ambient>
					<diffuse>0.88 0.45 0.08 1</diffuse>
				</material>
			</visual>
			<visual name="pedipalp_right_1">
		    	<pose>0.1 0.398 0 1.57 1.57 -0.4</pose>
				<geometry>
					<cylinder>
					    <length>0.2</length>
						<radius>0.02</radius>
					</cylinder>
				</geometry>
				<material>
				    <ambient>0.88 0.45 0.08 1</ambient>
					<diffuse>0.88 0.45 0.08 1</diffuse>
				</material>
			</visual>
			<visual name="pedipalp_right_2">
		    	<pose>0.1 0.57 0 1.57 1.57 0.4</pose>
				<geometry>
					<cylinder>
					    <length>0.2</length>
						<radius>0.02</radius>
					</cylinder>
				</geometry>
				<material>
				    <ambient>0.88 0.45 0.08 1</ambient>
					<diffuse>0.88 0.45 0.08 1</diffuse>
				</material>
			</visual>
		</link>
		
		<!-- Leg 1 links -->
		
		<!-- A temporary link, for the temporary solution of testing
		this file using revolute instead of universal joints -->
		<link name="trochanter_1">
			<pose>-0.124 0.315 0 0 0 0.59</pose>
			<inertial>
				<pose>0 0.05 0 1.57 1.57 0</pose>
				<mass>0.00047</mass>
				<inertia>
					<ixx>0.0000016</ixx>
					<ixy>0</ixy>
					<ixz>0</ixz>
					<iyy>0</iyy>
					<iyz>0</iyz>
					<izz>0.0000016</izz>
				</inertia>
			</inertial>
			<collision name="trochanter_1_collision">
				<pose>0 0.05 0 1.57 1.57 0</pose>
				<geometry>
					<cylinder>
						<length>0.1</length>
						<radius>0.04</radius>
					</cylinder>
				</geometry>
			</collision>
			<visual name="trochanter_1_visual">
				<pose>0 0.05 0 1.57 1.57 0</pose>
				<geometry>
					<cylinder>
						<length>0.1</length>
						<radius>0.04</radius>
					</cylinder>
				</geometry>
				<material>
					<ambient>0.88 0.45 0.08 1</ambient>
					<diffuse>0.88 0.45 0.08 1</diffuse>
				</material>
			</visual>
		</link>

		<link name="femur_1">
			<pose>-0.18 0.39 0 0 0 0.59</pose>
			<inertial>
				<pose>0 0.24 0 1.57 1.57 0</pose>
				<mass>0.00226</mass>
				<inertia>
					<ixx>0.000174</ixx>
					<ixy>0</ixy>
					<ixz>0</ixz>
					<iyy>0</iyy>
					<iyz>0</iyz>
					<izz>0.000174</izz>
				</inertia>
			</inertial>
			<collision name="femur_1_collision">
				<pose>0 0.24 0 1.57 1.57 0</pose>
				<geometry>
					<cylinder>
						<length>0.48</length>
						<radius>0.04</radius>
					</cylinder>
				</geometry>
			</collision>
			<visual name="femur_1_visual">
				<pose>0 0.24 0 1.57 1.57 0</pose>
				<geometry>
					<cylinder>
						<length>0.48</length>
						<radius>0.04</radius>
					</cylinder>
				</geometry>
				<material>
					<ambient>0.88 0.45 0.08 1</ambient>
					<diffuse>0.88 0.45 0.08 1</diffuse>
				</material>
			</visual>
		</link>
		
		<link name="tibia_1">
			<pose>-0.45 0.79 0 0 0 0.59</pose>
			<inertial>
				<pose>0 0.29 0 1.57 1.57 0</pose>
				<mass>0.00273</mass>
				<inertia>
					<ixx>0.000306</ixx>
					<ixy>0</ixy>
					<ixz>0</ixz>
					<iyy>0</iyy>
					<iyz>0</iyz>
					<izz>0.000306</izz>
				</inertia>
			</inertial>
			<collision name="tibia_1_collision">
				<pose>0 0.29 0 1.57 1.57 0</pose>
				<geometry>
					<cylinder>
						<length>0.58</length>
						<radius>0.04</radius>
					</cylinder>
				</geometry>
			</collision>
			<visual name="tibia_1_visual">
				<pose>0 0.29 0 1.57 1.57 0</pose>
				<geometry>
					<cylinder>
						<length>0.58</length>
						<radius>0.04</radius>
					</cylinder>
				</geometry>
				<material>
					<ambient>0.88 0.45 0.08 1</ambient>
					<diffuse>0.88 0.45 0.08 1</diffuse>
				</material>
			</visual>
		</link>
		
		<link name="tarsus_1">
			<pose>-0.78 1.28 0 0 0 0.59</pose>
			<inertial>
				<pose>0 0.19 0 1.57 1.57 0</pose>
				<mass>0.00179</mass>
				<inertia>
					<ixx>0.0000862</ixx>
					<ixy>0</ixy>
					<ixz>0</ixz>
					<iyy>0</iyy>
					<iyz>0</iyz>
					<izz>0.0000862</izz>
				</inertia>
			</inertial>
			<collision name="tarsus_1_collision">
				<pose>0 0.19 0 1.57 1.57 0</pose>
				<geometry>
					<cylinder>
						<length>0.38</length>
						<radius>0.04</radius>
					</cylinder>
				</geometry>
				<surface>
          			<friction>
            			<ode>
              				<mu>1</mu>
              				<mu2>1</mu2>
            			</ode>
          			</friction>
         		</surface>
			</collision>
			<visual name="tarsus_1_visual">
				<pose>0 0.19 0 1.57 1.57 0</pose>
				<geometry>
					<cylinder>
						<length>0.38</length>
						<radius>0.04</radius>
					</cylinder>
				</geometry>
				<material>
					<ambient>0.88 0.45 0.08 1</ambient>
					<diffuse>0.88 0.45 0.08 1</diffuse>
				</material>
			</visual>
		</link>
		
		<!-- Leg 1 joints -->
		
		<joint name="hip_1" type="revolute">
			<parent>body</parent>
			<child>trochanter_1</child>
			<axis>
				<!-- gazebo expects x-axis, pybullet expects y-axis -->
				<xyz>0 0 1</xyz>
				<limit>
					<lower>-1.61</lower>
					<upper>1.61</upper>
				</limit>
				<use_parent_model_frame>0</use_parent_model_frame>
			</axis>
		</joint>
		<joint name="hip2_1" type="revolute">
			<parent>trochanter_1</parent>
			<child>femur_1</child>
			<axis>
				<xyz>1 0 0</xyz>
				<limit>
					<lower>-0.916</lower>
					<upper>5.916</upper>
				</limit>
				<use_parent_model_frame>0</use_parent_model_frame>
			</axis>
		</joint>
		
		<joint name="knee_1" type="revolute">
			<parent>femur_1</parent>
			<child>tibia_1</child>
			<axis>
				<!-- gazebo expects x-axis, pybullet expects y-axis -->
				<xyz>1 0 0</xyz>
				<limit>
					<lower>-2.79</lower>
					<upper>0</upper>
				</limit>
			</axis>
		</joint>
		
		<joint name="ankle_1" type="revolute">
			<parent>tibia_1</parent>
			<child>tarsus_1</child>
			<axis>
				<!-- gazebo expects x-axis, pybullet expects y-axis -->
				<xyz>1 0 0</xyz>
				<limit>
					<lower>-0.61</lower>
					<upper>1.57</upper>
				</limit>
			</axis>
		</joint>
		
		<!-- Leg 2 links -->
		
		<!-- A temporary link, for the temporary solution of testing
		this file using revolute instead of universal joints -->
		<link name="trochanter_2">
			<pose>-0.169 0.268 0 0 0 1.28</pose>
			<inertial>
				<pose>0 0.05 0 1.57 1.57 0</pose>
				<mass>0.00047</mass>
				<inertia>
					<ixx>0.0000016</ixx>
					<ixy>0</ixy>
					<ixz>0</ixz>
					<iyy>0</iyy>
					<iyz>0</iyz>
					<izz>0.0000016</izz>
				</inertia>
			</inertial>
			<collision name="trochanter_2_collision">
				<pose>0 0.05 0 1.57 1.57 0</pose>
				<geometry>
					<cylinder>
						<length>0.1</length>
						<radius>0.04</radius>
					</cylinder>
				</geometry>
			</collision>
			<visual name="trochanter_2_visual">
				<pose>0 0.05 0 1.57 1.57 0</pose>
				<geometry>
					<cylinder>
						<length>0.1</length>
						<radius>0.04</radius>
					</cylinder>
				</geometry>
				<material>
					<ambient>0.88 0.45 0.08 1</ambient>
					<diffuse>0.88 0.45 0.08 1</diffuse>
				</material>
			</visual>
		</link>

		<link name="femur_2">
			<pose>-0.269 0.294 0 0 0 1.28</pose>
			<inertial>
				<pose>0 0.24 0 1.57 1.57 0</pose>
				<mass>0.00226</mass>
				<inertia>
					<ixx>0.000174</ixx>
					<ixy>0</ixy>
					<ixz>0</ixz>
					<iyy>0</iyy>
					<iyz>0</iyz>
					<izz>0.000174</izz>
				</inertia>
			</inertial>
			<collision name="femur_2_collision">
				<pose>0 0.24 0 1.57 1.57 0</pose>
				<geometry>
					<cylinder>
						<length>0.48</length>
						<radius>0.04</radius>
					</cylinder>
				</geometry>
			</collision>
			<visual name="femur_2_visual">
				<pose>0 0.24 0 1.57 1.57 0</pose>
				<geometry>
					<cylinder>
						<length>0.48</length>
						<radius>0.04</radius>
					</cylinder>
				</geometry>
				<material>
					<ambient>0.88 0.45 0.08 1</ambient>
					<diffuse>0.88 0.45 0.08 1</diffuse>
				</material>
			</visual>
		</link>
		
		<link name="tibia_2">
			<pose>-0.72 0.426 0 0 0 1.28</pose>
			<inertial>
				<pose>0 0.29 0 1.57 1.57 0</pose>
				<mass>0.00273</mass>
				<inertia>
					<ixx>0.000306</ixx>
					<ixy>0</ixy>
					<ixz>0</ixz>
					<iyy>0</iyy>
					<iyz>0</iyz>
					<izz>0.000306</izz>
				</inertia>
			</inertial>
			<collision name="tibia_2_collision">
				<pose>0 0.29 0 1.57 1.57 0</pose>
				<geometry>
					<cylinder>
						<length>0.58</length>
						<radius>0.04</radius>
					</cylinder>
				</geometry>
			</collision>
			<visual name="tibia_2_visual">
				<pose>0 0.29 0 1.57 1.57 0</pose>
				<geometry>
					<cylinder>
						<length>0.58</length>
						<radius>0.04</radius>
					</cylinder>
				</geometry>
				<material>
					<ambient>0.88 0.45 0.08 1</ambient>
					<diffuse>0.88 0.45 0.08 1</diffuse>
				</material>
			</visual>
		</link>
		
		<link name="tarsus_2">
			<pose>-1.29 0.590 0 0 0 1.28</pose>
			<inertial>
				<pose>0 0.19 0 1.57 1.57 0</pose>
				<mass>0.00179</mass>
				<inertia>
					<ixx>0.0000862</ixx>
					<ixy>0</ixy>
					<ixz>0</ixz>
					<iyy>0</iyy>
					<iyz>0</iyz>
					<izz>0.0000862</izz>
				</inertia>
			</inertial>
			<collision name="tarsus_2_collision">
				<pose>0 0.19 0 1.57 1.57 0</pose>
				<geometry>
					<cylinder>
						<length>0.38</length>
						<radius>0.04</radius>
					</cylinder>
				</geometry>
				<surface>
          			<friction>
            			<ode>
              				<mu>1</mu>
              				<mu2>1</mu2>
            			</ode>
          			</friction>
         		</surface>
			</collision>
			<visual name="tarsus_2_visual">
				<pose>0 0.19 0 1.57 1.57 0</pose>
				<geometry>
					<cylinder>
						<length>0.38</length>
						<radius>0.04</radius>
					</cylinder>
				</geometry>
				<material>
					<ambient>0.88 0.45 0.08 1</ambient>
					<diffuse>0.88 0.45 0.08 1</diffuse>
				</material>
			</visual>
		</link>
		
		<!-- Leg 2 joints -->
		
		<joint name="hip_2" type="revolute">
			<parent>body</parent>
			<child>trochanter_2</child>
			<axis>
				<!-- gazebo expects x-axis, pybullet expects y-axis -->
				<xyz>0 0 1</xyz>
				<limit>
					<lower>-1.61</lower>
					<upper>1.61</upper>
				</limit>
				<use_parent_model_frame>0</use_parent_model_frame>
			</axis>
		</joint>
		<joint name="hip2_2" type="revolute">
			<parent>trochanter_2</parent>
			<child>femur_2</child>
			<axis>
				<xyz>1 0 0</xyz>
				<limit>
					<lower>-0.916</lower>
					<upper>5.916</upper>
				</limit>
				<use_parent_model_frame>0</use_parent_model_frame>
			</axis>
		</joint>
		
		<joint name="knee_2" type="revolute">
			<parent>femur_2</parent>
			<child>tibia_2</child>
			<axis>
				<!-- gazebo expects x-axis, pybullet expects y-axis -->
				<xyz>1 0 0</xyz>
				<limit>
					<lower>-2.79</lower>
					<upper>0</upper>
				</limit>
			</axis>
		</joint>
		
		<joint name="ankle_2" type="revolute">
			<parent>tibia_2</parent>
			<child>tarsus_2</child>
			<axis>
				<!-- gazebo expects x-axis, pybullet expects y-axis -->
				<xyz>1 0 0</xyz>
				<limit>
					<lower>-0.61</lower>
					<upper>1.57</upper>
				</limit>
			</axis>
		</joint>
		

		<!-- Leg 3 links -->

		<!-- A temporary link, for the temporary solution of testing
		this file using revolute instead of universal joints -->
		<link name="trochanter_3">
			<pose>-0.169 0.178 0 0 0 2.332</pose>
			<inertial>
				<pose>0 0.05 0 1.57 1.57 0</pose>
				<mass>0.00047</mass>
				<inertia>
					<ixx>0.0000016</ixx>
					<ixy>0</ixy>
					<ixz>0</ixz>
					<iyy>0</iyy>
					<iyz>0</iyz>
					<izz>0.0000016</izz>
				</inertia>
			</inertial>
			<collision name="trochanter_3_collision">
				<pose>0 0.05 0 1.57 1.57 0</pose>
				<geometry>
					<cylinder>
						<length>0.1</length>
						<radius>0.04</radius>
					</cylinder>
				</geometry>
			</collision>
			<visual name="trochanter_3_visual">
				<pose>0 0.05 0 1.57 1.57 0</pose>
				<geometry>
					<cylinder>
						<length>0.1</length>
						<radius>0.04</radius>
					</cylinder>
				</geometry>
				<material>
					<ambient>0.88 0.45 0.08 1</ambient>
					<diffuse>0.88 0.45 0.08 1</diffuse>
				</material>
			</visual>
		</link>
		
		<link name="femur_3">
			<pose>-0.259 0.11 0 0 0 2.332</pose>
			<inertial>
				<pose>0 0.24 0 1.57 1.57 0</pose>
				<mass>0.00226</mass>
				<inertia>
					<ixx>0.000174</ixx>
					<ixy>0</ixy>
					<ixz>0</ixz>
					<iyy>0</iyy>
					<iyz>0</iyz>
					<izz>0.000174</izz>
				</inertia>
			</inertial>
			<collision name="femur_3_collision">
				<pose>0 0.24 0 1.57 1.57 0</pose>
				<geometry>
					<cylinder>
						<length>0.48</length>
						<radius>0.04</radius>
					</cylinder>
				</geometry>
			</collision>
			<visual name="femur_3_visual">
				<pose>0 0.24 0 1.57 1.57 0</pose>
				<geometry>
					<cylinder>
						<length>0.48</length>
						<radius>0.04</radius>
					</cylinder>
				</geometry>
				<material>
					<ambient>0.88 0.45 0.08 1</ambient>
					<diffuse>0.88 0.45 0.08 1</diffuse>
				</material>
			</visual>
		</link>
		
		<link name="tibia_3">
			<pose>-0.605 -0.235 0 0 0 2.332</pose>
			<inertial>
				<pose>0 0.29 0 1.57 1.57 0</pose>
				<mass>0.00273</mass>
				<inertia>
					<ixx>0.000306</ixx>
					<ixy>0</ixy>
					<ixz>0</ixz>
					<iyy>0</iyy>
					<iyz>0</iyz>
					<izz>0.000306</izz>
				</inertia>
			</inertial>
			<collision name="tibia_3_collision">
				<pose>0 0.29 0 1.57 1.57 0</pose>
				<geometry>
					<cylinder>
						<length>0.58</length>
						<radius>0.04</radius>
					</cylinder>
				</geometry>
			</collision>
			<visual name="tibia_3_visual">
				<pose>0 0.29 0 1.57 1.57 0</pose>
				<geometry>
					<cylinder>
						<length>0.58</length>
						<radius>0.04</radius>
					</cylinder>
				</geometry>
				<material>
					<ambient>0.88 0.45 0.08 1</ambient>
					<diffuse>0.88 0.45 0.08 1</diffuse>
				</material>
			</visual>
		</link>
		
		<link name="tarsus_3">
			<pose>-1.0 -0.62 0 0 0 2.332</pose>
			<inertial>
				<pose>0 0.19 0 1.57 1.57 0</pose>
				<mass>0.00179</mass>
				<inertia>
					<ixx>0.0000862</ixx>
					<ixy>0</ixy>
					<ixz>0</ixz>
					<iyy>0</iyy>
					<iyz>0</iyz>
					<izz>0.0000862</izz>
				</inertia>
			</inertial>
			<collision name="tarsus_3_collision">
				<pose>0 0.19 0 1.57 1.57 0</pose>
				<geometry>
					<cylinder>
						<length>0.38</length>
						<radius>0.04</radius>
					</cylinder>
				</geometry>
				<surface>
          			<friction>
            			<ode>
              				<mu>1</mu>
              				<mu2>1</mu2>
            			</ode>
          			</friction>
         		</surface>
			</collision>
			<visual name="tarsus_3_visual">
				<pose>0 0.19 0 1.57 1.57 0</pose>
				<geometry>
					<cylinder>
						<length>0.38</length>
						<radius>0.04</radius>
					</cylinder>
				</geometry>
				<material>
					<ambient>0.88 0.45 0.08 1</ambient>
					<diffuse>0.88 0.45 0.08 1</diffuse>
				</material>
			</visual>
		</link>
		
		<!-- Leg 3 joints -->
		
		<joint name="hip_3" type="revolute">
			<parent>body</parent>
			<child>trochanter_3</child>
			<axis>
				<!-- gazebo expects x-axis, pybullet expects y-axis -->
				<xyz>0 0 1</xyz>
				<limit>
					<lower>-1.61</lower>
					<upper>1.61</upper>
				</limit>
				<use_parent_model_frame>0</use_parent_model_frame>
			</axis>
		</joint>
		<joint name="hip2_3" type="revolute">
			<parent>trochanter_3</parent>
			<child>femur_3</child>
			<axis>
				<xyz>1 0 0</xyz>
				<limit>
					<lower>-0.916</lower>
					<upper>5.916</upper>
				</limit>
				<use_parent_model_frame>0</use_parent_model_frame>
			</axis>
		</joint>
		
		<joint name="knee_3" type="revolute">
			<parent>femur_3</parent>
			<child>tibia_3</child>
			<axis>
				<!-- gazebo expects x-axis, pybullet expects y-axis -->
				<xyz>1 0 0</xyz>
				<limit>
					<lower>-2.79</lower>
					<upper>0</upper>
				</limit>
			</axis>
		</joint>
		
		<joint name="ankle_3" type="revolute">
			<parent>tibia_3</parent>
			<child>tarsus_3</child>
			<axis>
				<!-- gazebo expects x-axis, pybullet expects y-axis -->
				<xyz>1 0 0</xyz>
				<limit>
					<lower>-0.61</lower>
					<upper>1.57</upper>
				</limit>
			</axis>
		</joint>
		

		<!-- Leg 4 links -->

		<!-- A temporary link, for the temporary solution of testing
		this file using revolute instead of universal joints -->
		<link name="trochanter_4">
			<pose>-0.124 0.131 0 0 0 3</pose>
			<inertial>
				<pose>0 0.05 0 1.57 1.57 0</pose>
				<mass>0.00047</mass>
				<inertia>
					<ixx>0.0000016</ixx>
					<ixy>0</ixy>
					<ixz>0</ixz>
					<iyy>0</iyy>
					<iyz>0</iyz>
					<izz>0.0000016</izz>
				</inertia>
			</inertial>
			<collision name="trochanter_4_collision">
				<pose>0 0.05 0 1.57 1.57 0</pose>
				<geometry>
					<cylinder>
						<length>0.1</length>
						<radius>0.04</radius>
					</cylinder>
				</geometry>
			</collision>
			<visual name="trochanter_4_visual">
				<pose>0 0.05 0 1.57 1.57 0</pose>
				<geometry>
					<cylinder>
						<length>0.1</length>
						<radius>0.04</radius>
					</cylinder>
				</geometry>
				<material>
					<ambient>0.88 0.45 0.08 1</ambient>
					<diffuse>0.88 0.45 0.08 1</diffuse>
				</material>
			</visual>
		</link>
		
		<link name="femur_4">
			<pose>-0.144 0.061 0 0 0 3</pose>
			<inertial>
				<pose>0 0.24 0 1.57 1.57 0</pose>
				<mass>0.00226</mass>
				<inertia>
					<ixx>0.000174</ixx>
					<ixy>0</ixy>
					<ixz>0</ixz>
					<iyy>0</iyy>
					<iyz>0</iyz>
					<izz>0.000174</izz>
				</inertia>
			</inertial>
			<collision name="femur_4_collision">
				<pose>0 0.24 0 1.57 1.57 0</pose>
				<geometry>
					<cylinder>
						<length>0.48</length>
						<radius>0.04</radius>
					</cylinder>
				</geometry>
			</collision>
			<visual name="femur_4_visual">
				<pose>0 0.24 0 1.57 1.57 0</pose>
				<geometry>
					<cylinder>
						<length>0.48</length>
						<radius>0.04</radius>
					</cylinder>
				</geometry>
				<material>
					<ambient>0.88 0.45 0.08 1</ambient>
					<diffuse>0.88 0.45 0.08 1</diffuse>
				</material>
			</visual>
		</link>
		
		<link name="tibia_4">
			<pose>-0.22 -0.40 0 0 0 3</pose>
			<inertial>
				<pose>0 0.29 0 1.57 1.57 0</pose>
				<mass>0.00273</mass>
				<inertia>
					<ixx>0.000306</ixx>
					<ixy>0</ixy>
					<ixz>0</ixz>
					<iyy>0</iyy>
					<iyz>0</iyz>
					<izz>0.000306</izz>
				</inertia>
			</inertial>
			<collision name="tibia_4_collision">
				<pose>0 0.29 0 1.57 1.57 0</pose>
				<geometry>
					<cylinder>
						<length>0.58</length>
						<radius>0.04</radius>
					</cylinder>
				</geometry>
			</collision>
			<visual name="tibia_4_visual">
				<pose>0 0.29 0 1.57 1.57 0</pose>
				<geometry>
					<cylinder>
						<length>0.58</length>
						<radius>0.04</radius>
					</cylinder>
				</geometry>
				<material>
					<ambient>0.88 0.45 0.08 1</ambient>
					<diffuse>0.88 0.45 0.08 1</diffuse>
				</material>
			</visual>
		</link>
		
		<link name="tarsus_4">
			<pose>-0.3 -0.97 0 0 0 3</pose>
			<inertial>
				<pose>0 0.19 0 1.57 1.57 0</pose>
				<mass>0.00179</mass>
				<inertia>
					<ixx>0.0000862</ixx>
					<ixy>0</ixy>
					<ixz>0</ixz>
					<iyy>0</iyy>
					<iyz>0</iyz>
					<izz>0.0000862</izz>
				</inertia>
			</inertial>
			<collision name="tarsus_4_collision">
				<pose>0 0.19 0 1.57 1.57 0</pose>
				<geometry>
					<cylinder>
						<length>0.38</length>
						<radius>0.04</radius>
					</cylinder>
				</geometry>
				<surface>
          			<friction>
            			<ode>
              				<mu>1</mu>
              				<mu2>1</mu2>
            			</ode>
          			</friction>
         		</surface>
			</collision>
			<visual name="tarsus_4_visual">
				<pose>0 0.19 0 1.57 1.57 0</pose>
				<geometry>
					<cylinder>
						<length>0.38</length>
						<radius>0.04</radius>
					</cylinder>
				</geometry>
				<material>
					<ambient>0.88 0.45 0.08 1</ambient>
					<diffuse>0.88 0.45 0.08 1</diffuse>
				</material>
			</visual>
		</link>
		
		<!-- Leg 4 joints -->
		
		<joint name="hip_4" type="revolute">
			<parent>body</parent>
			<child>trochanter_4</child>
			<axis>
				<!-- gazebo expects x-axis, pybullet expects y-axis -->
				<xyz>0 0 1</xyz>
				<limit>
					<lower>-1.61</lower>
					<upper>1.61</upper>
				</limit>
				<use_parent_model_frame>0</use_parent_model_frame>
			</axis>
		</joint>
		<joint name="hip2_4" type="revolute">
			<parent>trochanter_4</parent>
			<child>femur_4</child>
			<axis>
				<xyz>1 0 0</xyz>
				<limit>
					<lower>-0.916</lower>
					<upper>5.916</upper>
				</limit>
				<use_parent_model_frame>0</use_parent_model_frame>
			</axis>
		</joint>
		
		<joint name="knee_4" type="revolute">
			<parent>femur_4</parent>
			<child>tibia_4</child>
			<axis>
				<!-- gazebo expects x-axis, pybullet expects y-axis -->
				<xyz>1 0 0</xyz>
				<limit>
					<lower>-2.79</lower>
					<upper>0</upper>
				</limit>
			</axis>
		</joint>
		
		<joint name="ankle_4" type="revolute">
			<parent>tibia_4</parent>
			<child>tarsus_4</child>
			<axis>
				<!-- gazebo expects x-axis, pybullet expects y-axis -->
				<xyz>1 0 0</xyz>
				<limit>
					<lower>-0.61</lower>
					<upper>1.57</upper>
				</limit>
			</axis>
		</joint>
		

		<!-- Leg 5 links -->

		<!-- A temporary link, for the temporary solution of testing
		this file using revolute instead of universal joints -->
		<link name="trochanter_5">
			<pose>0.124 0.131 0 0 0 3.283</pose>
			<inertial>
				<pose>0 0.05 0 1.57 1.57 0</pose>
				<mass>0.00047</mass>
				<inertia>
					<ixx>0.0000016</ixx>
					<ixy>0</ixy>
					<ixz>0</ixz>
					<iyy>0</iyy>
					<iyz>0</iyz>
					<izz>0.0000016</izz>
				</inertia>
			</inertial>
			<collision name="trochanter_5_collision">
				<pose>0 0.05 0 1.57 1.57 0</pose>
				<geometry>
					<cylinder>
						<length>0.1</length>
						<radius>0.04</radius>
					</cylinder>
				</geometry>
			</collision>
			<visual name="trochanter_5_visual">
				<pose>0 0.05 0 1.57 1.57 0</pose>
				<geometry>
					<cylinder>
						<length>0.1</length>
						<radius>0.04</radius>
					</cylinder>
				</geometry>
				<material>
					<ambient>0.88 0.45 0.08 1</ambient>
					<diffuse>0.88 0.45 0.08 1</diffuse>
				</material>
			</visual>
		</link>
		
		<link name="femur_5">
			<pose>0.145 0.041 0 0 0 3.283</pose>
			<inertial>
				<pose>0 0.24 0 1.57 1.57 0</pose>
				<mass>0.00226</mass>
				<inertia>
					<ixx>0.000174</ixx>
					<ixy>0</ixy>
					<ixz>0</ixz>
					<iyy>0</iyy>
					<iyz>0</iyz>
					<izz>0.000174</izz>
				</inertia>
			</inertial>
			<collision name="femur_5_collision">
				<pose>0 0.24 0 1.57 1.57 0</pose>
				<geometry>
					<cylinder>
						<length>0.48</length>
						<radius>0.04</radius>
					</cylinder>
				</geometry>
			</collision>
			<visual name="femur_5_visual">
				<pose>0 0.24 0 1.57 1.57 0</pose>
				<geometry>
					<cylinder>
						<length>0.48</length>
						<radius>0.04</radius>
					</cylinder>
				</geometry>
				<material>
					<ambient>0.88 0.45 0.08 1</ambient>
					<diffuse>0.88 0.45 0.08 1</diffuse>
				</material>
			</visual>
		</link>
		
		<link name="tibia_5">
			<pose>0.214 -0.42 0 0 0 3.283</pose>
			<inertial>
				<pose>0 0.29 0 1.57 1.57 0</pose>
				<mass>0.00273</mass>
				<inertia>
					<ixx>0.000306</ixx>
					<ixy>0</ixy>
					<ixz>0</ixz>
					<iyy>0</iyy>
					<iyz>0</iyz>
					<izz>0.000306</izz>
				</inertia>
			</inertial>
			<collision name="tibia_5_collision">
				<pose>0 0.29 0 1.57 1.57 0</pose>
				<geometry>
					<cylinder>
						<length>0.58</length>
						<radius>0.04</radius>
					</cylinder>
				</geometry>
			</collision>
			<visual name="tibia_5_visual">
				<pose>0 0.29 0 1.57 1.57 0</pose>
				<geometry>
					<cylinder>
						<length>0.58</length>
						<radius>0.04</radius>
					</cylinder>
				</geometry>
				<material>
					<ambient>0.88 0.45 0.08 1</ambient>
					<diffuse>0.88 0.45 0.08 1</diffuse>
				</material>
			</visual>
		</link>
		
		<link name="tarsus_5">
			<pose>0.29 -0.98 0 0 0 3.283</pose>
			<inertial>
				<pose>0 0.19 0 1.57 1.57 0</pose>
				<mass>0.00179</mass>
				<inertia>
					<ixx>0.0000862</ixx>
					<ixy>0</ixy>
					<ixz>0</ixz>
					<iyy>0</iyy>
					<iyz>0</iyz>
					<izz>0.0000862</izz>
				</inertia>
			</inertial>
			<collision name="tarsus_5_collision">
				<pose>0 0.19 0 1.57 1.57 0</pose>
				<geometry>
					<cylinder>
						<length>0.38</length>
						<radius>0.04</radius>
					</cylinder>
				</geometry>
				<surface>
          			<friction>
            			<ode>
              				<mu>1</mu>
              				<mu2>1</mu2>
            			</ode>
          			</friction>
         		</surface>
			</collision>
			<visual name="tarsus_5_visual">
				<pose>0 0.19 0 1.57 1.57 0</pose>
				<geometry>
					<cylinder>
						<length>0.38</length>
						<radius>0.04</radius>
					</cylinder>
				</geometry>
				<material>
					<ambient>0.88 0.45 0.08 1</ambient>
					<diffuse>0.88 0.45 0.08 1</diffuse>
				</material>
			</visual>
		</link>
		
		<!-- Leg 5 joints -->
		
		<joint name="hip_5" type="revolute">
			<parent>body</parent>
			<child>trochanter_5</child>
			<axis>
				<!-- gazebo expects x-axis, pybullet expects y-axis -->
				<xyz>0 0 1</xyz>
				<limit>
					<lower>-1.61</lower>
					<upper>1.61</upper>
				</limit>
				<use_parent_model_frame>0</use_parent_model_frame>
			</axis>
		</joint>
		<joint name="hip2_5" type="revolute">
			<parent>trochanter_5</parent>
			<child>femur_5</child>
			<axis>
				<xyz>1 0 0</xyz>
				<limit>
					<lower>-0.916</lower>
					<upper>5.916</upper>
				</limit>
				<use_parent_model_frame>0</use_parent_model_frame>
			</axis>
		</joint>
		
		<joint name="knee_5" type="revolute">
			<parent>femur_5</parent>
			<child>tibia_5</child>
			<axis>
				<!-- gazebo expects x-axis, pybullet expects y-axis -->
				<xyz>1 0 0</xyz>
				<limit>
					<lower>-2.79</lower>
					<upper>0</upper>
				</limit>
			</axis>
		</joint>
		
		<joint name="ankle_5" type="revolute">
			<parent>tibia_5</parent>
			<child>tarsus_5</child>
			<axis>
				<!-- gazebo expects x-axis, pybullet expects y-axis -->
				<xyz>1 0 0</xyz>
				<limit>
					<lower>-0.61</lower>
					<upper>1.57</upper>
				</limit>
			</axis>
		</joint>
		

		<!-- Leg 6 links -->

		<!-- A temporary link, for the temporary solution of testing
		this file using revolute instead of universal joints -->
		<link name="trochanter_6">
			<pose>0.169 0.178 0 0 0 3.951</pose>
			<inertial>
				<pose>0 0.05 0 1.57 1.57 0</pose>
				<mass>0.00047</mass>
				<inertia>
					<ixx>0.0000016</ixx>
					<ixy>0</ixy>
					<ixz>0</ixz>
					<iyy>0</iyy>
					<iyz>0</iyz>
					<izz>0.0000016</izz>
				</inertia>
			</inertial>
			<collision name="trochanter_6_collision">
				<pose>0 0.05 0 1.57 1.57 0</pose>
				<geometry>
					<cylinder>
						<length>0.1</length>
						<radius>0.04</radius>
					</cylinder>
				</geometry>
			</collision>
			<visual name="trochanter_6_visual">
				<pose>0 0.05 0 1.57 1.57 0</pose>
				<geometry>
					<cylinder>
						<length>0.1</length>
						<radius>0.04</radius>
					</cylinder>
				</geometry>
				<material>
					<ambient>0.88 0.45 0.08 1</ambient>
					<diffuse>0.88 0.45 0.08 1</diffuse>
				</material>
			</visual>
		</link>
		
		<link name="femur_6">
			<pose>0.23 0.128 0 0 0 3.951</pose>
			<inertial>
				<pose>0 0.24 0 1.57 1.57 0</pose>
				<mass>0.00226</mass>
				<inertia>
					<ixx>0.000174</ixx>
					<ixy>0</ixy>
					<ixz>0</ixz>
					<iyy>0</iyy>
					<iyz>0</iyz>
					<izz>0.000174</izz>
				</inertia>
			</inertial>
			<collision name="femur_6_collision">
				<pose>0 0.24 0 1.57 1.57 0</pose>
				<geometry>
					<cylinder>
						<length>0.48</length>
						<radius>0.04</radius>
					</cylinder>
				</geometry>
			</collision>
			<visual name="femur_6_visual">
				<pose>0 0.24 0 1.57 1.57 0</pose>
				<geometry>
					<cylinder>
						<length>0.48</length>
						<radius>0.04</radius>
					</cylinder>
				</geometry>
				<material>
					<ambient>0.88 0.45 0.08 1</ambient>
					<diffuse>0.88 0.45 0.08 1</diffuse>
				</material>
			</visual>
		</link>
		
		<link name="tibia_6">
			<pose>0.58 -0.2 0 0 0 3.951</pose>
			<inertial>
				<pose>0 0.29 0 1.57 1.57 0</pose>
				<mass>0.00273</mass>
				<inertia>
					<ixx>0.000306</ixx>
					<ixy>0</ixy>
					<ixz>0</ixz>
					<iyy>0</iyy>
					<iyz>0</iyz>
					<izz>0.000306</izz>
				</inertia>
			</inertial>
			<collision name="tibia_6_collision">
				<pose>0 0.29 0 1.57 1.57 0</pose>
				<geometry>
					<cylinder>
						<length>0.58</length>
						<radius>0.04</radius>
					</cylinder>
				</geometry>
			</collision>
			<visual name="tibia_6_visual">
				<pose>0 0.29 0 1.57 1.57 0</pose>
				<geometry>
					<cylinder>
						<length>0.58</length>
						<radius>0.04</radius>
					</cylinder>
				</geometry>
				<material>
					<ambient>0.88 0.45 0.08 1</ambient>
					<diffuse>0.88 0.45 0.08 1</diffuse>
				</material>
			</visual>
		</link>
		
		<link name="tarsus_6">
			<pose>1 -0.59 0 0 0 3.951</pose>
			<inertial>
				<pose>0 0.19 0 1.57 1.57 0</pose>
				<mass>0.00179</mass>
				<inertia>
					<ixx>0.0000862</ixx>
					<ixy>0</ixy>
					<ixz>0</ixz>
					<iyy>0</iyy>
					<iyz>0</iyz>
					<izz>0.0000862</izz>
				</inertia>
			</inertial>
			<collision name="tarsus_6_collision">
				<pose>0 0.19 0 1.57 1.57 0</pose>
				<geometry>
					<cylinder>
						<length>0.38</length>
						<radius>0.04</radius>
					</cylinder>
				</geometry>
				<surface>
          			<friction>
            			<ode>
              				<mu>1</mu>
              				<mu2>1</mu2>
            			</ode>
          			</friction>
         		</surface>
			</collision>
			<visual name="tarsus_6_visual">
				<pose>0 0.19 0 1.57 1.57 0</pose>
				<geometry>
					<cylinder>
						<length>0.38</length>
						<radius>0.04</radius>
					</cylinder>
				</geometry>
				<material>
					<ambient>0.88 0.45 0.08 1</ambient>
					<diffuse>0.88 0.45 0.08 1</diffuse>
				</material>
			</visual>
		</link>
		
		<!-- Leg 6 joints -->
		
		<joint name="hip_6" type="revolute">
			<parent>body</parent>
			<child>trochanter_6</child>
			<axis>
				<!-- gazebo expects x-axis, pybullet expects y-axis -->
				<xyz>0 0 1</xyz>
				<limit>
					<lower>-1.61</lower>
					<upper>1.61</upper>
				</limit>
				<use_parent_model_frame>0</use_parent_model_frame>
			</axis>
		</joint>
		<joint name="hip2_6" type="revolute">
			<parent>trochanter_6</parent>
			<child>femur_6</child>
			<axis>
				<xyz>1 0 0</xyz>
				<limit>
					<lower>-0.916</lower>
					<upper>5.916</upper>
				</limit>
				<use_parent_model_frame>0</use_parent_model_frame>
			</axis>
		</joint>
		
		<joint name="knee_6" type="revolute">
			<parent>femur_6</parent>
			<child>tibia_6</child>
			<axis>
				<!-- gazebo expects x-axis, pybullet expects y-axis -->
				<xyz>1 0 0</xyz>
				<limit>
					<lower>-2.79</lower>
					<upper>0</upper>
				</limit>
			</axis>
		</joint>
		
		<joint name="ankle_6" type="revolute">
			<parent>tibia_6</parent>
			<child>tarsus_6</child>
			<axis>
				<!-- gazebo expects x-axis, pybullet expects y-axis -->
				<xyz>1 0 0</xyz>
				<limit>
					<lower>-0.61</lower>
					<upper>1.57</upper>
				</limit>
			</axis>
		</joint>
		
		<!-- Leg 7 links -->

		<!-- A temporary link, for the temporary solution of testing
		this file using revolute instead of universal joints -->
		<link name="trochanter_7">
			<pose>0.169 0.268 0 0 0 5</pose>
			<inertial>
				<pose>0 0.05 0 1.57 1.57 0</pose>
				<mass>0.00047</mass>
				<inertia>
					<ixx>0.0000016</ixx>
					<ixy>0</ixy>
					<ixz>0</ixz>
					<iyy>0</iyy>
					<iyz>0</iyz>
					<izz>0.0000016</izz>
				</inertia>
			</inertial>
			<collision name="trochanter_7_collision">
				<pose>0 0.05 0 1.57 1.57 0</pose>
				<geometry>
					<cylinder>
						<length>0.1</length>
						<radius>0.04</radius>
					</cylinder>
				</geometry>
			</collision>
			<visual name="trochanter_7_visual">
				<pose>0 0.05 0 1.57 1.57 0</pose>
				<geometry>
					<cylinder>
						<length>0.1</length>
						<radius>0.04</radius>
					</cylinder>
				</geometry>
				<material>
					<ambient>0.88 0.45 0.08 1</ambient>
					<diffuse>0.88 0.45 0.08 1</diffuse>
				</material>
			</visual>
		</link>
		
		<link name="femur_7">
			<pose>0.27 0.298 0 0 0 5</pose>
			<inertial>
				<pose>0 0.24 0 1.57 1.57 0</pose>
				<mass>0.00226</mass>
				<inertia>
					<ixx>0.000174</ixx>
					<ixy>0</ixy>
					<ixz>0</ixz>
					<iyy>0</iyy>
					<iyz>0</iyz>
					<izz>0.000174</izz>
				</inertia>
			</inertial>
			<collision name="femur_7_collision">
				<pose>0 0.24 0 1.57 1.57 0</pose>
				<geometry>
					<cylinder>
						<length>0.48</length>
						<radius>0.04</radius>
					</cylinder>
				</geometry>
			</collision>
			<visual name="femur_7_visual">
				<pose>0 0.24 0 1.57 1.57 0</pose>
				<geometry>
					<cylinder>
						<length>0.48</length>
						<radius>0.04</radius>
					</cylinder>
				</geometry>
				<material>
					<ambient>0.88 0.45 0.08 1</ambient>
					<diffuse>0.88 0.45 0.08 1</diffuse>
				</material>
			</visual>
		</link>
		
		<link name="tibia_7">
			<pose>0.7 0.44 0 0 0 5</pose>
			<inertial>
				<pose>0 0.29 0 1.57 1.57 0</pose>
				<mass>0.00273</mass>
				<inertia>
					<ixx>0.000306</ixx>
					<ixy>0</ixy>
					<ixz>0</ixz>
					<iyy>0</iyy>
					<iyz>0</iyz>
					<izz>0.000306</izz>
				</inertia>
			</inertial>
			<collision name="tibia_7_collision">
				<pose>0 0.29 0 1.57 1.57 0</pose>
				<geometry>
					<cylinder>
						<length>0.58</length>
						<radius>0.04</radius>
					</cylinder>
				</geometry>
			</collision>
			<visual name="tibia_7_visual">
				<pose>0 0.29 0 1.57 1.57 0</pose>
				<geometry>
					<cylinder>
						<length>0.58</length>
						<radius>0.04</radius>
					</cylinder>
				</geometry>
				<material>
					<ambient>0.88 0.45 0.08 1</ambient>
					<diffuse>0.88 0.45 0.08 1</diffuse>
				</material>
			</visual>
		</link>
		
		<link name="tarsus_7">
			<pose>1.25 0.61 0 0 0 5</pose>
			<inertial>
				<pose>0 0.19 0 1.57 1.57 0</pose>
				<mass>0.00179</mass>
				<inertia>
					<ixx>0.0000862</ixx>
					<ixy>0</ixy>
					<ixz>0</ixz>
					<iyy>0</iyy>
					<iyz>0</iyz>
					<izz>0.0000862</izz>
				</inertia>
			</inertial>
			<collision name="tarsus_7_collision">
				<pose>0 0.19 0 1.57 1.57 0</pose>
				<geometry>
					<cylinder>
						<length>0.38</length>
						<radius>0.04</radius>
					</cylinder>
				</geometry>
				<surface>
          			<friction>
            			<ode>
              				<mu>1</mu>
              				<mu2>1</mu2>
            			</ode>
          			</friction>
         		</surface>
			</collision>
			<visual name="tarsus_7_visual">
				<pose>0 0.19 0 1.57 1.57 0</pose>
				<geometry>
					<cylinder>
						<length>0.38</length>
						<radius>0.04</radius>
					</cylinder>
				</geometry>
				<material>
					<ambient>0.88 0.45 0.08 1</ambient>
					<diffuse>0.88 0.45 0.08 1</diffuse>
				</material>
			</visual>
		</link>
		
		<!-- Leg 7 joints -->
		
		<joint name="hip_7" type="revolute">
			<parent>body</parent>
			<child>trochanter_7</child>
			<axis>
				<!-- gazebo expects x-axis, pybullet expects y-axis -->
				<xyz>0 0 1</xyz>
				<limit>
					<lower>-1.61</lower>
					<upper>1.61</upper>
				</limit>
				<use_parent_model_frame>0</use_parent_model_frame>
			</axis>
		</joint>
		<joint name="hip2_7" type="revolute">
			<parent>trochanter_7</parent>
			<child>femur_7</child>
			<axis>
				<xyz>1 0 0</xyz>
				<limit>
					<lower>-0.916</lower>
					<upper>5.916</upper>
				</limit>
				<use_parent_model_frame>0</use_parent_model_frame>
			</axis>
		</joint>
		
		<joint name="knee_7" type="revolute">
			<parent>femur_7</parent>
			<child>tibia_7</child>
			<axis>
				<!-- gazebo expects x-axis, pybullet expects y-axis -->
				<xyz>1 0 0</xyz>
				<limit>
					<lower>-2.79</lower>
					<upper>0</upper>
				</limit>
			</axis>
		</joint>
		
		<joint name="ankle_7" type="revolute">
			<parent>tibia_7</parent>
			<child>tarsus_7</child>
			<axis>
				<!-- gazebo expects x-axis, pybullet expects y-axis -->
				<xyz>1 0 0</xyz>
				<limit>
					<lower>-0.61</lower>
					<upper>1.57</upper>
				</limit>
			</axis>
		</joint>
		

		<!-- Leg 8 links -->

		<!-- A temporary link, for the temporary solution of testing
		this file using revolute instead of universal joints -->
		<link name="trochanter_8">
			<pose>0.124 0.315 0 0 0 5.693</pose>
			<inertial>
				<pose>0 0.05 0 1.57 1.57 0</pose>
				<mass>0.00047</mass>
				<inertia>
					<ixx>0.0000016</ixx>
					<ixy>0</ixy>
					<ixz>0</ixz>
					<iyy>0</iyy>
					<iyz>0</iyz>
					<izz>0.0000016</izz>
				</inertia>
			</inertial>
			<collision name="trochanter_8_collision">
				<pose>0 0.05 0 1.57 1.57 0</pose>
				<geometry>
					<cylinder>
						<length>0.1</length>
						<radius>0.04</radius>
					</cylinder>
				</geometry>
			</collision>
			<visual name="trochanter_8_visual">
				<pose>0 0.05 0 1.57 1.57 0</pose>
				<geometry>
					<cylinder>
						<length>0.1</length>
						<radius>0.04</radius>
					</cylinder>
				</geometry>
				<material>
					<ambient>0.88 0.45 0.08 1</ambient>
					<diffuse>0.88 0.45 0.08 1</diffuse>
				</material>
			</visual>
		</link>
		
		<link name="femur_8">
			<pose>0.17 0.385 0 0 0 5.693</pose>
			<inertial>
				<pose>0 0.24 0 1.57 1.57 0</pose>
				<mass>0.00226</mass>
				<inertia>
					<ixx>0.000174</ixx>
					<ixy>0</ixy>
					<ixz>0</ixz>
					<iyy>0</iyy>
					<iyz>0</iyz>
					<izz>0.000174</izz>
				</inertia>
			</inertial>
			<collision name="femur_8_collision">
				<pose>0 0.24 0 1.57 1.57 0</pose>
				<geometry>
					<cylinder>
						<length>0.48</length>
						<radius>0.04</radius>
					</cylinder>
				</geometry>
			</collision>
			<visual name="femur_8_visual">
				<pose>0 0.24 0 1.57 1.57 0</pose>
				<geometry>
					<cylinder>
						<length>0.48</length>
						<radius>0.04</radius>
					</cylinder>
				</geometry>
				<material>
					<ambient>0.88 0.45 0.08 1</ambient>
					<diffuse>0.88 0.45 0.08 1</diffuse>
				</material>
			</visual>
		</link>
		
		<link name="tibia_8">
		    <pose>0.43 0.78 0 0 0 5.693</pose>
			<inertial>
				<pose>0 0.29 0 1.57 1.57 0</pose>
				<mass>0.00273</mass>
				<inertia>
					<ixx>0.000306</ixx>
					<ixy>0</ixy>
					<ixz>0</ixz>
					<iyy>0</iyy>
					<iyz>0</iyz>
					<izz>0.000306</izz>
				</inertia>
			</inertial>
			<collision name="tibia_8_collision">
				<pose>0 0.29 0 1.57 1.57 0</pose>
				<geometry>
					<cylinder>
						<length>0.58</length>
						<radius>0.04</radius>
					</cylinder>
				</geometry>
			</collision>
			<visual name="tibia_8_visual">
				<pose>0 0.29 0 1.57 1.57 0</pose>
				<geometry>
					<cylinder>
						<length>0.58</length>
						<radius>0.04</radius>
					</cylinder>
				</geometry>
				<material>
					<ambient>0.88 0.45 0.08 1</ambient>
					<diffuse>0.88 0.45 0.08 1</diffuse>
				</material>
			</visual>
		</link>
		
		
		<link name="tarsus_8">
			<pose>0.75 1.26 0 0 0 5.693</pose>
			<inertial>
				<pose>0 0.19 0 1.57 1.57 0</pose>
				<mass>0.00179</mass>
				<inertia>
					<ixx>0.0000862</ixx>
					<ixy>0</ixy>
					<ixz>0</ixz>
					<iyy>0</iyy>
					<iyz>0</iyz>
					<izz>0.0000862</izz>
				</inertia>
			</inertial>
			<collision name="tarsus_8_collision">
				<pose>0 0.19 0 1.57 1.57 0</pose>
				<geometry>
					<cylinder>
						<length>0.38</length>
						<radius>0.04</radius>
					</cylinder>
				</geometry>
				<surface>
          			<friction>
            			<ode>
              				<mu>1</mu>
              				<mu2>1</mu2>
            			</ode>
          			</friction>
         		</surface>
			</collision>
			<visual name="tarsus_8_visual">
				<pose>0 0.19 0 1.57 1.57 0</pose>
				<geometry>
					<cylinder>
						<length>0.38</length>
						<radius>0.04</radius>
					</cylinder>
				</geometry>
				<material>
					<ambient>0.88 0.45 0.08 1</ambient>
					<diffuse>0.88 0.45 0.08 1</diffuse>
				</material>
			</visual>
		</link>
		
		<!-- Leg 8 joints -->

		<joint name="hip_8" type="revolute">
			<parent>body</parent>
			<child>trochanter_8</child>
	
			<axis>
				<!-- gazebo expects x-axis, pybullet expects y-axis -->
				<xyz>0 0 1</xyz>
				<limit>
					<lower>-1.61</lower>
					<upper>1.61</upper>
				</limit>
				<use_parent_model_frame>0</use_parent_model_frame>
			</axis>
		</joint>
		<joint name="hip2_8" type="revolute">
			<parent>trochanter_8</parent>
			<child>femur_8</child>
			<axis>
				<xyz>1 0 0</xyz>
				<limit>
					<lower>-0.916</lower>
					<upper>5.916</upper>
				</limit>
				<use_parent_model_frame>0</use_parent_model_frame>
			</axis>
		</joint>
		
		<joint name="knee_8" type="revolute">
			<parent>femur_8</parent>
			<child>tibia_8</child>
			<axis>
				<!-- gazebo expects x-axis, pybullet expects y-axis -->

				<xyz>1 0 0</xyz>
				<limit>
					<lower>-2.79</lower>
					<upper>0</upper>
				</limit>
			</axis>
		</joint>
		
		<joint name="ankle_8" type="revolute">
			<parent>tibia_8</parent>
			<child>tarsus_8</child>
			<axis>
				<!-- gazebo expects x-axis, pybullet expects y-axis -->
				<xyz>1 0 0</xyz>
				<limit>
					<lower>-0.61</lower>
					<upper>1.57</upper>
				</limit>
			</axis>
		</joint>
		

	</model>
</world>
</sdf>
