<?xml version="1.0" ?>

<robot name="ngr_simple" xmlns:xacro="http://www.ros.org/wiki/xacro">

<!-- Define materials -->
  <material name="gray">
    <color rgba="0.5 0.5 0.5 0.7"/>
  </material>
  <material name="black">
    <color rgba="0.0 0.0 0.0 0.7"/>
  </material>
  <material name="blue">
    <color rgba="0 0 1 0.8"/>
  </material>
  <material name="red">
    <color rgba="0.8 0.0 0.2 0.8"/>
  </material>
  <material name="purple">
    <color rgba="0.5 0.0 0.5 0.8"/>
  </material>
  <material name="green">
    <color rgba="0.0 1.0 0.0 0.8"/>
  </material>
  <material name="cyan">
    <color rgba="0.0 0.8 0.8 0.8"/>
  </material>

   <!-- Body -->
  <link name="body">
    <visual>
      <origin rpy="0 0 0" xyz="0 0 0"/>
      <geometry>
        <box size="0.3 0.3 0.1"/>
      </geometry>
      <material name="gray"/>
    </visual>
    <inertial>
      <mass value="12"/>
      <inertia ixx="0.0986" ixy="0" ixz="0" iyy="0.8105" iyz="0" izz="0.8369"/>
    </inertial>
    <collision>
      <geometry>
        <box size="0.3 0.3 0.1"/>
      </geometry>
    </collision>
  </link>

  <!-- Leg #1 -->
  <!-- Hip motor -->
  <link name="hip0">
    <visual>
      <origin rpy="0 0 0" xyz="0.0 0 0"/>
      <geometry>
        <sphere radius="0.05"/>
      </geometry>
      <material name="red"/>
    </visual>
    <collision>
      <origin rpy="0 0 0" xyz="0.0 0 0"/>
      <geometry>
        <sphere radius="0.05"/>
      </geometry>
    </collision>
    <inertial>
      <mass value="2.75"/>
      <inertia ixx="0.00891458" ixy="0" ixz="0" iyy="0.0100573" iyz="0" izz="0.01533698"/>
    </inertial>
  </link>

  <!-- Abduction joint. Joint names are: 8 9 10 11 -->
  <joint name="8" type="continuous">
    <parent link="body"/>
    <child link="hip0"/>
    <axis xyz="0 0 1"/>
    <!-- origin in relation to child frame origin-->
    <origin xyz="0.15 0.15 0" rpy="0 0 0.7075"/>
    <!-- <limit effort="375" velocity="8.6"/> -->
    <dynamics damping="0.0" friction="0.0"/>
  </joint>

  <!-- Upper leg -->
  <link name="upper0">
    <visual>
      <origin rpy="0 0 0" xyz="-0.15 0.0 0"/>
      <geometry>
        <box size="0.3 0.05 0.05"/>
      </geometry>
      <material name="blue"/>
    </visual>
    <collision>
      <origin rpy="0 0 0" xyz="-0.15 0 0"/>
      <geometry>
        <box size="0.3 0.05 0.05"/>
      </geometry>
    </collision>
    <inertial>
      <mass value="0.625"/>
      <origin rpy="0 0 0" xyz="-0.15 0 0"/>
      <inertia ixx="0.0003125" ixy="0" ixz="0" iyy="0.0040625" iyz="0" izz="0.0040625"/>
    </inertial>
  </link>

  <!-- Hip joint. (Motor to upper leg). Joint names are: 0 2 4 6 -->
  <joint name="0" type="continuous">
    <parent link="hip0"/>
    <child link="upper0"/>
    <axis xyz="0 1 0"/> <!-- Hip joint axis aligned with knee -->
    <origin xyz="0 0 0" rpy="0 0.7075 3.14159"/>
    <!-- <limit effort="87.5" velocity="30"/> -->
    <dynamics damping="0.0" friction="0.0"/>
  </joint>

  <!-- Lower leg -->
  <link name="lower0">
    <visual>
      <origin rpy="0 1.5707963268 0" xyz="-0.14 0 0"/>
      <geometry>
        <cylinder length="0.28" radius="0.011"/>
      </geometry>
      <material name="black"/>
    </visual>
    <visual>
      <origin rpy="0 1.5707963268 0" xyz="-0.14 0 0"/>
      <geometry>
        <sphere radius="0.011"/>
      </geometry>
      <material name="green"/>
    </visual>
    <collision>
      <origin rpy="0 1.5707963268 0" xyz="-0.14 0 0"/>
      <geometry>
        <cylinder length="0.28" radius="0.011"/>
      </geometry>
    </collision>
    <collision>
      <origin rpy="0 1.5707963268 0" xyz="-0.14 0 0"/>
      <geometry>
        <sphere radius="0.011"/>
      </geometry>
    </collision>
    <inertial>
      <origin rpy="0 0 0" xyz="0.14 0 0"/>
      <mass value="0.2"/>
      <inertia ixx="0.0000121" ixy="0" ixz="0" iyy="0.0013127167" iyz="0" izz="0.0013127167"/>
    </inertial>
  </link>

  <!-- Knee joint. Joint names are: 1 3 5 7 -->
  <joint name="1" type="continuous">
    <parent link="upper0"/>
    <child link="lower0"/>
    <axis xyz="0 1 0"/>
    <origin xyz="-0.28 0 0" rpy="0 -1.57 0"/>
    <!-- <limit effort="87.5" lower="0" upper="3.14159265359" velocity="30"/> -->
    <dynamics damping="0.0" friction="0.0"/>
  </joint>
  
  <!-- Grabber -->
  <link name="grab0">
    <visual>
      <origin rpy="0 0 0" xyz="0.01 0 0"/>
      <geometry>
        <sphere radius="0.02"/>
      </geometry>
      <material name="red"/>
    </visual>
    <collision>
      <origin rpy="0 0 0" xyz="0.01 0 0"/>
      <geometry>
        <sphere radius="0.02"/>
      </geometry>
    </collision>
    <inertial>
      <origin rpy="0 0 0" xyz="0.01 0 0"/>
      <mass value="0.2"/>
      <inertia ixx="0.0000121" ixy="0" ixz="0" iyy="0.0013127167" iyz="0" izz="0.0013127167"/>
    </inertial>
  </link>

  <!-- Grabber Joint. Joint names are 12 13 14 15 -->
  <joint name="12" type="fixed">
    <parent link="lower0"/>
    <child link="grab0"/>
    <axis xyz="1 0 0"/>
    <origin xyz="-0.28 0 0" rpy="0 0 0"/>
    <!-- <limit effort="87.5" lower="0" upper="3.14159265359" velocity="30"/> -->
    <!-- <dynamics damping="0.0" friction="0.0"/> -->
  </joint>

  <!-- Leg #2 -->
  <!-- Hip motor -->
  <link name="hip1">
    <visual>
      <origin rpy="0 0 0" xyz="0.0 0 0"/>
      <geometry>
        <sphere radius="0.05"/>
      </geometry>
      <material name="purple"/>
    </visual>
    <collision>
      <origin rpy="0 0 0" xyz="0.0 0 0"/>
      <geometry>
        <sphere radius="0.05"/>
      </geometry>
    </collision>
    <inertial>
      <mass value="2.75"/>
      <inertia ixx="0.00891458" ixy="0" ixz="0" iyy="0.0100573" iyz="0" izz="0.01533698"/>
    </inertial>
  </link>
  
  <!-- Abduction joint. Joint names are: 8 9 10 11 -->
  <joint name="9" type="continuous">
    <parent link="body"/>
    <child link="hip1"/>
    <axis xyz="0 0 1"/>
    <origin xyz="-0.15 0.15 0" rpy="0 0 -0.7075"/>
    <!-- <limit effort="375" velocity="8.6"/> -->
    <dynamics damping="0.0" friction="0.0"/>
  </joint>

  <!-- Upper leg -->
  <link name="upper1">
    <visual>
      <origin rpy="0 0 0" xyz="-0.15 0.0 0"/>
      <geometry>
        <box size="0.3 0.05 0.05"/>
      </geometry>
      <material name="blue"/>
    </visual>
    <collision>
      <origin rpy="0 0 0" xyz="-0.15 0 0"/>
      <geometry>
        <box size="0.3 0.05 0.05"/>
      </geometry>
    </collision>
    <inertial>
      <mass value="0.625"/>
      <origin rpy="0 0 0" xyz="-0.15 0 0"/>
      <inertia ixx="0.0003125" ixy="0" ixz="0" iyy="0.0040625" iyz="0" izz="0.0040625"/>
    </inertial>
  </link>

  <!-- Hip joint. (Motor to upper leg). Joint names are: 0 2 4 6 -->
  <joint name="2" type="continuous">
    <parent link="hip1"/>
    <child link="upper1"/>
    <axis xyz="0 1 0"/>
    <origin xyz="0 0 0" rpy="0 0.7075 0"/>
    <!-- <limit effort="87.5" velocity="30"/> -->
    <dynamics damping="0.0" friction="0.0"/>
  </joint>

  <!-- Lower leg -->
  <link name="lower1">
    <visual>
      <origin rpy="0 1.5707963268 0" xyz="-0.14 0 0"/>
      <geometry>
        <cylinder length="0.28" radius="0.011"/>
      </geometry>
      <material name="black"/>
    </visual>
    <visual>
      <origin rpy="0 1.5707963268 0" xyz="-0.14 0 0"/>
      <geometry>
        <sphere radius="0.011"/>
      </geometry>
      <material name="green"/>
    </visual>
    <collision>
      <origin rpy="0 1.5707963268 0" xyz="-0.14 0 0"/>
      <geometry>
        <cylinder length="0.28" radius="0.011"/>
      </geometry>
    </collision>
    <collision>
      <origin rpy="0 1.5707963268 0" xyz="-0.14 0 0"/>
      <geometry>
        <sphere radius="0.011"/>
      </geometry>
    </collision>
    <inertial>
      <origin rpy="0 0 0" xyz="0.14 0 0"/>
      <mass value="0.2"/>
      <inertia ixx="0.0000121" ixy="0" ixz="0" iyy="0.0013127167" iyz="0" izz="0.0013127167"/>
    </inertial>
  </link>

  <!-- Knee joint. Joint names are: 1 3 5 7 -->
  <joint name="3" type="continuous">
    <parent link="upper1"/>
    <child link="lower1"/>
    <axis xyz="0 1 0"/>
    <origin xyz="-0.28 0 0" rpy="0 -1.57 0"/>
    <!-- <limit effort="87.5" lower="0" upper="3.14159265359" velocity="30"/> -->
    <dynamics damping="0.0" friction="0.0"/>
  </joint>

  <!-- Grabber -->
  <link name="grab1">
    <visual>
      <origin rpy="0 0 0" xyz="0.01 0 0"/>
      <geometry>
        <sphere radius="0.02"/>
      </geometry>
      <material name="purple"/>
    </visual>
    <collision>
      <origin rpy="0 0 0" xyz="0.01 0 0"/>
      <geometry>
        <sphere radius="0.02"/>
      </geometry>
    </collision>
    <inertial>
      <origin rpy="0 0 0" xyz="0.01 0 0"/>
      <mass value="0.2"/>
      <inertia ixx="0.0000121" ixy="0" ixz="0" iyy="0.0013127167" iyz="0" izz="0.0013127167"/>
    </inertial>
  </link>

  <!-- Grabber Joint. Joint names are 12 13 14 15 -->
  <joint name="13" type="fixed">
    <parent link="lower1"/>
    <child link="grab1"/>
    <axis xyz="1 0 0"/>
    <origin xyz="-0.28 0 0" rpy="0 0 0"/>
    <!-- <limit effort="87.5" lower="0" upper="3.14159265359" velocity="30"/> -->
    <!-- <dynamics damping="0.0" friction="0.0"/> -->
  </joint>

  <!-- Leg #3 -->
  <!-- Hip motor -->
  <link name="hip2">
    <visual>
      <origin rpy="0 0 0" xyz="0.0 0 0"/>
      <geometry>
        <sphere radius="0.05"/>
      </geometry>
      <material name="green"/>
    </visual>
    <collision>
      <origin rpy="0 0 0" xyz="0.0 0 0"/>
      <geometry>
        <sphere radius="0.05"/>
      </geometry>
    </collision>
    <inertial>
      <mass value="2.75"/>
      <inertia ixx="0.00891458" ixy="0" ixz="0" iyy="0.0100573" iyz="0" izz="0.01533698"/>
    </inertial>
  </link>

  <!-- Abduction joint. Joint names are: 8 9 10 11 -->
  <joint name="10" type="continuous">
    <parent link="body"/>
    <child link="hip2"/>
    <axis xyz="0 0 1"/>
    <origin xyz="0.15 -0.15 0" rpy="0 0 -0.7075"/>
    <!-- <limit effort="375" velocity="8.6"/> -->
    <dynamics damping="0.0" friction="0.0"/>
  </joint>

  <!-- Upper leg -->
  <link name="upper2">
    <visual>
      <origin rpy="0 0 0" xyz="-0.15 0.0 0"/>
      <geometry>
        <box size="0.3 0.05 0.05"/>
      </geometry>
      <material name="blue"/>
    </visual>
    <collision>
      <origin rpy="0 0 0" xyz="-0.15 0 0"/>
      <geometry>
        <box size="0.3 0.05 0.05"/>
      </geometry>
    </collision>
    <inertial>
      <mass value="0.625"/>
      <origin rpy="0 0 0" xyz="-0.15 0 0"/>
      <inertia ixx="0.0003125" ixy="0" ixz="0" iyy="0.0040625" iyz="0" izz="0.0040625"/>
    </inertial>
  </link>

  <!-- Hip joint. (Motor to upper leg). Joint names are: 0 2 4 6 -->
  <joint name="4" type="continuous">
    <parent link="hip2"/>
    <child link="upper2"/>
    <axis xyz="0 1 0"/>
    <origin xyz="0 0 0" rpy="0 0.7075 3.14159"/>
    <!-- <limit effort="87.5" velocity="30"/> -->
    <dynamics damping="0.0" friction="0.0"/>
  </joint>

  <!-- Lower leg -->
  <link name="lower2">
    <visual>
      <origin rpy="0 1.5707963268 0" xyz="-0.14 0 0"/>
      <geometry>
        <cylinder length="0.28" radius="0.011"/>
      </geometry>
      <material name="black"/>
    </visual>
    <visual>
      <origin rpy="0 1.5707963268 0" xyz="-0.14 0 0"/>
      <geometry>
        <sphere radius="0.011"/>
      </geometry>
      <material name="green"/>
    </visual>
    <collision>
      <origin rpy="0 1.5707963268 0" xyz="-0.14 0 0"/>
      <geometry>
        <cylinder length="0.28" radius="0.011"/>
      </geometry>
    </collision>
    <collision>
      <origin rpy="0 1.5707963268 0" xyz="-0.14 0 0"/>
      <geometry>
        <sphere radius="0.011"/>
      </geometry>
    </collision>
    <inertial>
      <origin rpy="0 0 0" xyz="0.14 0 0"/>
      <mass value="0.2"/>
      <inertia ixx="0.0000121" ixy="0" ixz="0" iyy="0.0013127167" iyz="0" izz="0.0013127167"/>
    </inertial>
  </link>

  <!-- Knee joint. Joint names are: 1 3 5 7 -->
  <joint name="5" type="continuous">
    <parent link="upper2"/>
    <child link="lower2"/>
    <axis xyz="0 1 0"/>
    <origin xyz="-0.28 0 0" rpy="0 -1.57 0"/>
    <!-- <limit effort="87.5" lower="0" upper="3.14159265359" velocity="30"/> -->
    <dynamics damping="0.0" friction="0.0"/>
  </joint>

  <!-- Grabber -->
  <link name="grab2">
    <visual>
      <origin rpy="0 0 0" xyz="0.01 0 0"/>
      <geometry>
        <sphere radius="0.02"/>
      </geometry>
      <material name="green"/>
    </visual>
    <collision>
      <origin rpy="0 0 0" xyz="0.01 0 0"/>
      <geometry>
        <sphere radius="0.02"/>
      </geometry>
    </collision>
    <inertial>
      <origin rpy="0 0 0" xyz="0.01 0 0"/>
      <mass value="0.2"/>
      <inertia ixx="0.0000121" ixy="0" ixz="0" iyy="0.0013127167" iyz="0" izz="0.0013127167"/>
    </inertial>
  </link>

  <!-- Grabber Joint. Joint names are 12 13 14 15 -->
  <joint name="14" type="fixed">
    <parent link="lower2"/>
    <child link="grab2"/>
    <axis xyz="1 0 0"/>
    <origin xyz="-0.28 0 0" rpy="0 0 0"/>
    <!-- <limit effort="87.5" lower="0" upper="3.14159265359" velocity="30"/> -->
    <!-- <dynamics damping="0.0" friction="0.0"/> -->
  </joint>

  <!-- Leg #4 -->
  <!-- Hip motor -->
  <link name="hip3">
    <visual>
      <origin rpy="0 0 0" xyz="0.0 0 0"/>
      <geometry>
        <sphere radius="0.05"/>
      </geometry>
      <material name="cyan"/>
    </visual>
    <collision>
      <origin rpy="0 0 0" xyz="0.0 0 0"/>
      <geometry>
        <sphere radius="0.05"/>
      </geometry>
    </collision>
    <inertial>
      <mass value="2.75"/>
      <inertia ixx="0.00891458" ixy="0" ixz="0" iyy="0.0100573" iyz="0" izz="0.01533698"/>
    </inertial>
  </link>

  <!-- Abduction joint. Joint names are: 8 9 10 11 -->
  <joint name="11" type="continuous">
    <parent link="body"/>
    <child link="hip3"/>
    <axis xyz="0 0 1"/>
    <origin xyz="-0.15 -0.15 0" rpy="0 0 0.7075"/>
    <!-- <limit effort="375" velocity="8.6"/> -->
    <dynamics damping="0.0" friction="0.0"/>
  </joint>

  <!-- Upper leg -->
  <link name="upper3">
    <visual>
      <origin rpy="0 0 0" xyz="-0.15 0.0 0"/>
      <geometry>
        <box size="0.3 0.05 0.05"/>
      </geometry>
      <material name="blue"/>
    </visual>
    <collision>
      <origin rpy="0 0 0" xyz="-0.15 0 0"/>
      <geometry>
        <box size="0.3 0.05 0.05"/>
      </geometry>
    </collision>
    <inertial>
      <mass value="0.625"/>
      <origin rpy="0 0 0" xyz="-0.15 0 0"/>
      <inertia ixx="0.0003125" ixy="0" ixz="0" iyy="0.0040625" iyz="0" izz="0.0040625"/>
    </inertial>
  </link>

  <!-- Hip joint. (Motor to upper leg). Joint names are: 0 2 4 6 -->
  <joint name="6" type="continuous">
    <parent link="hip3"/>
    <child link="upper3"/>
    <axis xyz="0 1 0"/>
    <origin xyz="0 0 0" rpy="0 0.7075 0"/>
    <!-- <limit effort="87.5" velocity="30"/> -->
    <dynamics damping="0.0" friction="0.0"/>
  </joint>

  <!-- Lower leg -->
  <link name="lower3">
    <visual>
      <origin rpy="0 1.5707963268 0" xyz="-0.14 0 0"/>
      <geometry>
        <cylinder length="0.28" radius="0.011"/>
      </geometry>
      <material name="black"/>
    </visual>
    <visual>
      <origin rpy="0 1.5707963268 0" xyz="-0.14 0 0"/>
      <geometry>
        <sphere radius="0.011"/>
      </geometry>
      <material name="green"/>
    </visual>
    <collision>
      <origin rpy="0 1.5707963268 0" xyz="-0.14 0 0"/>
      <geometry>
        <cylinder length="0.28" radius="0.011"/>
      </geometry>
    </collision>
    <collision>
      <origin rpy="0 1.5707963268 0" xyz="-0.14 0 0"/>
      <geometry>
        <sphere radius="0.011"/>
      </geometry>
    </collision>
    <inertial>
      <origin rpy="0 0 0" xyz="0.14 0 0"/>
      <mass value="0.2"/>
      <inertia ixx="0.0000121" ixy="0" ixz="0" iyy="0.0013127167" iyz="0" izz="0.0013127167"/>
    </inertial>
  </link>

  <!-- Knee joint. Joint names are: 1 3 5 7 -->
  <joint name="7" type="continuous">
    <parent link="upper3"/>
    <child link="lower3"/>
    <axis xyz="0 1 0"/>
    <origin xyz="-0.28 0 0" rpy="0 -1.57 0"/>
    <!-- <limit effort="87.5" lower="0" upper="3.14159265359" velocity="30"/> -->
    <dynamics damping="0.0" friction="0.0"/>
  </joint>

  <!-- Grabber -->
  <link name="grab3">
    <visual>
      <origin rpy="0 0 0" xyz="0.01 0 0"/>
      <geometry>
        <sphere radius="0.02"/>
      </geometry>
      <material name="cyan"/>
    </visual>
    <collision>
      <origin rpy="0 0 0" xyz="0.01 0 0"/>
      <geometry>
        <sphere radius="0.02"/>
      </geometry>
    </collision>
    <inertial>
      <origin rpy="0 0 0" xyz="0.01 0 0"/>
      <mass value="0.2"/>
      <inertia ixx="0.0000121" ixy="0" ixz="0" iyy="0.0013127167" iyz="0" izz="0.0013127167"/>
    </inertial>
  </link>

  <!-- Grabber Joint. Joint names are 12 13 14 15 -->
  <joint name="15" type="fixed">
    <parent link="lower3"/>
    <child link="grab3"/>
    <axis xyz="1 0 0"/>
    <origin xyz="-0.28 0 0" rpy="0 0 0"/>
    <!-- <limit effort="87.5" lower="0" upper="3.14159265359" velocity="30"/> -->
    <!-- <dynamics damping="0.0" friction="0.0"/> -->
  </joint>
</robot>