<?xml version='1.0' encoding='utf-8'?>
<robot name="panda">
  <link name="link0">
    <visual>
      <geometry>
        <mesh filename="visual/link0.dae"/>
      </geometry>
    </visual>
    <collision>
      <origin xyz="-0.075 0 0.06" rpy="0 1.5707963268 0"/>
      <geometry>
        <cylinder radius="0.06" length="0.03" />
      </geometry>
    </collision>
    <collision>
      <origin xyz="-0.06 0 0.06" rpy="0 0 0"/>
      <geometry>
        <sphere radius="0.06" />
      </geometry>
    </collision>
    <collision>
      <origin xyz="-0.09 0 0.06" rpy="0 0 0"/>
      <geometry>
        <sphere radius="0.06" />
      </geometry>
    </collision>
  </link>
  <link name="link1">
    <visual>
      <geometry>
        <mesh filename="visual/link1.dae"/>
      </geometry>
    </visual>
    <collision>
      <origin xyz="0 0 -0.1915" rpy="0 0 0"/>
      <geometry>
        <cylinder radius="0.06" length="0.2830" />
      </geometry>
    </collision>
    <collision>
      <origin xyz="0 0 -0.333" rpy="0 0 0"/>
      <geometry>
        <sphere radius="0.06" />
      </geometry>
    </collision>
    <collision>
      <origin xyz="0 0 -0.05" rpy="0 0 0"/>
      <geometry>
        <sphere radius="0.06" />
      </geometry>
    </collision>
  </link>
  <joint name="joint1" type="revolute">
    <safety_controller k_position="100.0" k_velocity="40.0" soft_lower_limit="-2.8973" soft_upper_limit="2.8973"/>
    <origin rpy="0 0 0" xyz="0 0 0.333"/>
    <parent link="link0"/>
    <child link="link1"/>
    <axis xyz="0 0 1"/>
    <limit effort="87" lower="-2.8973" upper="2.8973" velocity="2.1750"/>
  </joint>
  <link name="link2">
    <visual>
      <geometry>
        <mesh filename="visual/link2.dae"/>
      </geometry>
    </visual>
    <collision>
      <origin xyz="0 0 0" rpy="0 0 0"/>
      <geometry>
        <cylinder radius="0.06" length="0.12" />
      </geometry>
    </collision>
    <collision>
      <origin xyz="0 0 -0.06" rpy="0 0 0"/>
      <geometry>
        <sphere radius="0.06" />
      </geometry>
    </collision>
    <collision>
      <origin xyz="0 0 0.06" rpy="0 0 0"/>
      <geometry>
        <sphere radius="0.06" />
      </geometry>
    </collision>
  </link>
  <joint name="joint2" type="revolute">
    <safety_controller k_position="100.0" k_velocity="40.0" soft_lower_limit="-1.7628" soft_upper_limit="1.7628"/>
    <origin rpy="-1.5707963268 0 0" xyz="0 0 0"/>
    <parent link="link1"/>
    <child link="link2"/>
    <axis xyz="0 0 1"/>
    <limit effort="87" lower="-1.7628" upper="1.7628" velocity="2.1750"/>
  </joint>
  <link name="link3">
    <visual>
      <geometry>
        <mesh filename="visual/link3.dae"/>
      </geometry>
    </visual>
    <collision>
      <origin xyz="0 0 -0.145" rpy="0 0 0"/>
      <geometry>
        <cylinder radius="0.06" length="0.15" />
      </geometry>
    </collision>
    <collision>
      <origin xyz="0 0 -0.22" rpy="0 0 0"/>
      <geometry>
        <sphere radius="0.06" />
      </geometry>
    </collision>
    <collision>
      <origin xyz="0 0 -0.07" rpy="0 0 0"/>
      <geometry>
        <sphere radius="0.06" />
      </geometry>
    </collision>
  </link>
  <joint name="joint3" type="revolute">
    <safety_controller k_position="100.0" k_velocity="40.0" soft_lower_limit="-2.8973" soft_upper_limit="2.8973"/>
    <origin rpy="1.5707963268 0 0" xyz="0 -0.316 0"/>
    <parent link="link2"/>
    <child link="link3"/>
    <axis xyz="0 0 1"/>
    <limit effort="87" lower="-2.8973" upper="2.8973" velocity="2.1750"/>
  </joint>
  <link name="link4">
    <visual>
      <geometry>
        <mesh filename="visual/link4.dae"/>
      </geometry>
    </visual>
    <collision>
      <origin xyz="0 0 0" rpy="0 0 0"/>
      <geometry>
        <cylinder radius="0.06" length="0.12" />
      </geometry>
    </collision>
    <collision>
      <origin xyz="0 0 0.06" rpy="0 0 0"/>
      <geometry>
        <sphere radius="0.06" />
      </geometry>
    </collision>
    <collision>
      <origin xyz="0 0 -0.06" rpy="0 0 0"/>
      <geometry>
        <sphere radius="0.06" />
      </geometry>
    </collision>
  </link>
  <joint name="joint4" type="revolute">
    <safety_controller k_position="100.0" k_velocity="40.0" soft_lower_limit="-3.0718" soft_upper_limit="-0.0698"/>
    <origin rpy="1.5707963268 0 0" xyz="0.0825 0 0"/>
    <parent link="link3"/>
    <child link="link4"/>
    <axis xyz="0 0 1"/>
    <limit effort="87" lower="-3.0718" upper="-0.0698" velocity="2.1750"/>
  </joint>
  <link name="link5">
    <visual>
      <geometry>
        <mesh filename="visual/link5.dae"/>
      </geometry>
    </visual>
    <collision>
      <origin xyz="0 0 -0.26" rpy="0 0 0"/>
      <geometry>
        <cylinder radius="0.06" length="0.1" />
      </geometry>
    </collision>
    <collision>
      <origin xyz="0 0 -0.31" rpy="0 0 0"/>
      <geometry>
        <sphere radius="0.06" />
      </geometry>
    </collision>
    <collision>
      <origin xyz="0 0 -0.21" rpy="0 0 0"/>
      <geometry>
        <sphere radius="0.06" />
      </geometry>
    </collision>
    <collision>
      <origin xyz="0 0.08 -0.13" rpy="0 0 0"/>
      <geometry>
        <cylinder radius="0.025" length="0.14" />
      </geometry>
    </collision>
    <collision>
      <origin xyz="0 0.08 -0.06" rpy="0 0 0"/>
      <geometry>
        <sphere radius="0.025" />
      </geometry>
    </collision>
    <collision>
      <origin xyz="0 0.08 -0.20" rpy="0 0 0"/>
      <geometry>
        <sphere radius="0.025" />
      </geometry>
    </collision>

  </link>
  <joint name="joint5" type="revolute">
    <safety_controller k_position="100.0" k_velocity="40.0" soft_lower_limit="-2.8973" soft_upper_limit="2.8973"/>
    <origin rpy="-1.5707963268 0 0" xyz="-0.0825 0.384 0"/>
    <parent link="link4"/>
    <child link="link5"/>
    <axis xyz="0 0 1"/>
    <limit effort="12" lower="-2.8973" upper="2.8973" velocity="2.6100"/>
  </joint>
  <link name="link6">
    <visual>
      <geometry>
        <mesh filename="visual/link6.dae"/>
      </geometry>
    </visual>
    <collision>
      <origin xyz="0 0 -0.03" rpy="0 0 0"/>
      <geometry>
        <cylinder radius="0.05" length="0.08" />
      </geometry>
    </collision>
    <collision>
      <origin xyz="0 0 0.01" rpy="0 0 0"/>
      <geometry>
        <sphere radius="0.05" />
      </geometry>
    </collision>
    <collision>
      <origin xyz="0 0 -0.07" rpy="0 0 0"/>
      <geometry>
        <sphere radius="0.05" />
      </geometry>
    </collision>
  </link>
  <joint name="joint6" type="revolute">
    <safety_controller k_position="100.0" k_velocity="40.0" soft_lower_limit="-0.0175" soft_upper_limit="3.7525"/>
    <origin rpy="1.5707963268 0 0" xyz="0 0 0"/>
    <parent link="link5"/>
    <child link="link6"/>
    <axis xyz="0 0 1"/>
    <limit effort="12" lower="-0.0175" upper="3.7525" velocity="2.6100"/>
  </joint>
  <link name="link7">
    <visual>
      <geometry>
        <mesh filename="visual/link7.dae"/>
      </geometry>
    </visual>
    <collision>
      <origin xyz="0 0 0.01" rpy="0 0 0"/>
      <geometry>
        <cylinder radius="0.04" length="0.14" />
      </geometry>
    </collision>
    <collision>
      <origin xyz="0 0 0.08" rpy="0 0 0"/>
      <geometry>
        <sphere radius="0.04" />
      </geometry>
    </collision>
    <collision>
      <origin xyz="0 0 -0.06" rpy="0 0 0"/>
      <geometry>
        <sphere radius="0.04" />
      </geometry>
    </collision>
  </link>
  <joint name="joint7" type="revolute">
    <safety_controller k_position="100.0" k_velocity="40.0" soft_lower_limit="-2.8973" soft_upper_limit="2.8973"/>
    <origin rpy="1.5707963268 0 0" xyz="0.088 0 0"/>
    <parent link="link6"/>
    <child link="link7"/>
    <axis xyz="0 0 1"/>
    <limit effort="12" lower="-2.8973" upper="2.8973" velocity="2.6100"/>
  </joint>
  <link name="link8">
    <collision>
      <origin xyz="0.0424 0.0424 -0.0250" rpy="3.141592653589793 1.5707963268 1.5707963268"/>
      <geometry>
        <cylinder radius="0.03" length="0.01" />
      </geometry>
    </collision>
    <collision>
      <origin xyz="0.0424 0.0424 -0.02" rpy="0 0 0"/>
      <geometry>
        <sphere radius="0.03" />
      </geometry>
    </collision>
    <collision>
      <origin xyz="0.0424 0.0424 -0.03" rpy="0 0 0"/>
      <geometry>
        <sphere radius="0.03" />
      </geometry>
    </collision>
  </link>
  <joint name="joint8" type="fixed">
    <origin rpy="0 0 0" xyz="0 0 0.107"/>
    <parent link="link7"/>
    <child link="link8"/>
  </joint>
</robot>